Workbook

Sheet Info
A1: Data Dummy RL 3.2 untuk Latihan Input SIRS 6.3 (Clone)
A3: DEMO: sandbox latihan input SIRS. Bukan aplikasi resmi Kemenkes.
A4: Rumah sakit: RS Umum Demo Basangdata (fiktif).
A5: Periode: September 2024 s.d. Agustus 2026 (24 bulan, satu sheet per bulan).
A7: CARA PAKAI
A8: 1. Login ke aplikasi latihan (user1 / basangdata), buka menu RL 3.2 Rawat Inap.
A9: 2. Pilih tahun dan bulan sesuai sheet (misal sheet 2024-09 = September 2024), klik Tambah.
A10: 3. Salin angka dari Excel ke kolom isian dengan urutan yang sama.
A11: 4. Kolom berlatar kuning (Pasien Akhir Bulan, Jumlah Hari Perawatan) dihitung otomatis
A12: oleh SIRS, jangan disalin. Baris TOTAL juga tidak perlu diinput.
A13: 5. Simpan, lalu ulangi untuk bulan berikutnya secara berurutan.
A15: ATURAN YANG SUDAH DIPENUHI DATA INI
... A30: DAFTAR PERIODE
A32: Sheet | B32: Periode
A33: 2024-09 | B33: September 2024
A34: 2024-10 | B34: Oktober 2024
A35: 2024-11 | B35: November 2024
A36: 2024-12 | B36: Desember 2024
A37: 2025-01 | B37: Januari 2025
A38: 2025-02 | B38: Februari 2025
A39: 2025-03 | B39: Maret 2025
A40: 2025-04 | B40: April 2025
A41: 2025-05 | B41: Mei 2025
A42: 2025-06 | B42: Juni 2025
A43: 2025-07 | B43: Juli 2025
... A56: 2026-08 | B56: Agustus 2026

Sheet 2024-09
A1: RL 3.2 - Rekapitulasi Kegiatan Pelayanan Rawat Inap - September 2024
A2: RS Umum Demo Basangdata (fiktif) | DEMO: sandbox latihan input SIRS. Bukan aplikasi resmi Kemenkes.
A4: No | B4: Jenis Pelayanan | C4: Pasien Awal Bulan | D4: Pasien Masuk | E4: Pasien Pindahan | F4: Pasien Dipindahkan | G4: Pasien Keluar Hidup | H4: Pasien Laki-Laki Keluar Mati < 48 jam | I4: Pasien Laki-Laki Keluar Mati ≥ 48 jam | J4: Pasien Perempuan Keluar Mati < 48 jam | K4: Pasien Perempuan Keluar Mati ≥ 48 jam | L4: Jumlah Lama Dirawat | M4: Pasien Akhir Bulan (otomatis) | N4: Jumlah Hari Perawatan (otomatis) | O4: Hari Perawatan Kelas VVIP | P4: Hari Perawatan Kelas VIP | Q4: Hari Perawatan Kelas I | R4: Hari Perawatan Kelas II | S4: Hari Perawatan Kelas III | T4: Hari Perawatan Kelas Khusus | U4: Jumlah Alokasi Tempat Tidur Awal Bulan
A5: 1 | B5: Umum | C5: 15 | D5: 98 | E5: 7 | F5: 4 | G5: 99 | H5: 0 | I5: 0 | J5: 0 | K5: 0 | L5: 411 | M5: =C5+D5+E5-F5-G5-H5-I5-J5-K5 -> 17 | N5: =SUM(O5:T5) -> 453 | O5: 0 | P5: 9 | Q5: 36 | R5: 82 | S5: 308 | T5: 18 | U5: 24
A6: 2 | B6: Penyakit Dalam | C6: 13 | D6: 76 | E6: 5 | F6: 4 | G6: 76 | H6: 0 | I6: 0 | J6: 0 | K6: 0 | L6: 355 | M6: =C6+D6+E6-F6-G6-H6-I6-J6-K6 -> 14 | N6: =SUM(O6:T6) -> 380 | O6: 0 | P6: 8 | Q6: 38 | R6: 76 | S6: 235 | T6: 23 | U6: 20
A7: 3 | B7: Kesehatan Anak | C7: 7 | D7: 61 | E7: 4 | F7: 3 | G7: 60 | H7: 1 | I7: 0 | J7: 0 | K7: 1 | L7: 214 | M7: =C7+D7+E7-F7-G7-H7-I7-J7-K7 -> 7 | N7: =SUM(O7:T7) -> 230 | O7: 0 | P7: 5 | Q7: 23 | R7: 46 | S7: 142 | T7: 14 | U7: 12
A8: 4 | B8: Kesehatan Remaja | C8: 2 | D8: 12 | E8: 1 | F8: 1 | G8: 12 | H8: 0 | I8: 0 | J8: 0 | K8: 0 | L8: 46 | M8: =C8+D8+E8-F8-G8-H8-I8-J8-K8 -> 2 | N8: =SUM(O8:T8) -> 49 | O8: 0 | P8: 1 | Q8: 5 | R8: 10 | S8: 30 | T8: 3 | U8: 4
A9: 5 | B9: Obstetri | C9: 9 | D9: 87 | E9: 5 | F9: 5 | G9: 86 | H9: 0 | I9: 0 | J9: 0 | K9: 0 | L9: 268 | M9: =C9+D9+E9-F9-G9-H9-I9-J9-K9 -> 10 | N9: =SUM(O9:T9) -> 294 | O9: 0 | P9: 9 | Q9: 35 | R9: 73 | S9: 171 | T9: 6 | U9: 14
A10: 6 | B10: Ginekologi | C10: 3 | D10: 19 | E10: 1 | F10: 1 | G10: 19 | H10: 0 | I10: 0 | J10: 0 | K10: 0 | L10: 86 | M10: =C10+D10+E10-F10-G10-H10-I10-J10-K10 -> 3 | N10: =SUM(O10:T10) -> 89 | O10: 0 | P10: 2 | Q10: 9 | R10: 18 | S10: 55 | T10: 5 | U10: 6
A11: 7 | B11: Bedah | C11: 8 | D11: 49 | E11: 3 | F11: 2 | G11: 48 | H11: 0 | I11: 1 | J11: 0 | K11: 0 | L11: 233 | M11: =C11+D11+E11-F11-G11-H11-I11-J11-K11 -> 9 | N11: =SUM(O11:T11) -> 256 | O11: 0 | P11: 8 | Q11: 31 | R11: 56 | S11: 153 | T11: 8 | U11: 14
A12: 8 | B12: Bedah Orthopedi | C12: 4 | D12: 19 | E12: 1 | F12: 1 | G12: 17 | H12: 0 | I12: 1 | J12: 0 | K12: 0 | L12: 126 | M12: =C12+D12+E12-F12-G12-H12-I12-J12-K12 -> 5 | N12: =SUM(O12:T12) -> 131 | O12: 0 | P12: 4 | Q12: 16 | R12: 29 | S12: 78 | T12: 4 | U12: 8
A13: 9 | B13: Bedah Saraf | C13: 2 | D13: 8 | E13: 1 | F13: 1 | G13: 8 | H13: 0 | I13: 0 | J13: 0 | K13: 0 | L13: 56 | M13: =C13+D13+E13-F13-G13-H13-I13-J13-K13 -> 2 | N13: =SUM(O13:T13) -> 58 | O13: 0 | P13: 2 | Q13: 7 | R13: 13 | S13: 35 | T13: 1 | U13: 4
A14: 10 | B14: Luka Bakar | C14: 0 | D14: 0 | E14: 0 | F14: 0 | G14: 0 | H14: 0 | I14: 0 | J14: 0 | K14: 0 | L14: 0 | M14: =C14+D14+E14-F14-G14-H14-I14-J14-K14 -> 0 | N14: =SUM(O14:T14) -> 0 | O14: 0 | P14: 0 | Q14: 0 | R14: 0 | S14: 0 | T14: 0 | U14: 0
A15: 11 | B15: Saraf | C15: 0 | D15: 0 | E15: 0 | F15: 0 | G15: 0 | H15: 0 | I15: 0 | J15: 0 | K15: 0 | L15: 0 | M15: =C15+D15+E15-F15-G15-H15-I15-J15-K15 -> 0 | N15: =SUM(O15:T15) -> 0 | O15: 0 | P15: 0 | Q15: 0 | R15: 0 | S15: 0 | T15: 0 | U15: 0
A16: 12 | B16: Jiwa | C16: 0 | D16: 0 | E16: 0 | F16: 0 | G16: 0 | H16: 0 | I16: 0 | J16: 0 | K16: 0 | L16: 0 | M16: =C16+D16+E16-F16-G16-H16-I16-J16-K16 -> 0 | N16: =SUM(O16:T16) -> 0 | O16: 0 | P16: 0 | Q16: 0 | R16: 0 | S16: 0 | T16: 0 | U16: 0
... A40: 36 | B40: Perinatologi | C40: 4 | D40: 17 | E40: 4 | F40: 3 | G40: 16 | H40: 1 | I40: 0 | J40: 0 | K40: 1 | L40: 107 | M40: =C40+D40+E40-F40-G40-H40-I40-J40-K40 -> 4 | N40: =SUM(O40:T40) -> 113 | O40: 0 | P40: 0 | Q40: 0 | R40: 6 | S40: 28 | T40: 79 | U40: 6
A41: 99 | B41: TOTAL | C41: =SUM(C5:C40) -> 114 | D41: =SUM(D5:D40) -> 725 | E41: =SUM(E5:E40) -> 82 | F41: =SUM(F5:F40) -> 86 | G41: =SUM(G5:G40) -> 692 | H41: =SUM(H5:H40) -> 4 | I41: =SUM(I5:I40) -> 9 | J41: =SUM(J5:J40) -> 0 | ... U41: =SUM(U5:U40) -> 196

Sheet 2024-10
A1: RL 3.2 - Rekapitulasi Kegiatan Pelayanan Rawat Inap - Oktober 2024
A2: RS Umum Demo Basangdata (fiktif) | DEMO: sandbox latihan input SIRS. Bukan aplikasi resmi Kemenkes.
A4: No | B4: Jenis Pelayanan | C4: Pasien Awal Bulan | D4: Pasien Masuk | E4: Pasien Pindahan | F4: Pasien Dipindahkan | G4: Pasien Keluar Hidup | H4: Pasien Laki-Laki Keluar Mati < 48 jam | I4: Pasien Laki-Laki Keluar Mati ≥ 48 jam | J4: Pasien Perempuan Keluar Mati < 48 jam | K4: Pasien Perempuan Keluar Mati ≥ 48 jam | L4: Jumlah Lama Dirawat | M4: Pasien Akhir Bulan (otomatis) | N4: Jumlah Hari Perawatan (otomatis) | O4: Hari Perawatan Kelas VVIP | P4: Hari Perawatan Kelas VIP | Q4: Hari Perawatan Kelas I | R4: Hari Perawatan Kelas II | S4: Hari Perawatan Kelas III | T4: Hari Perawatan Kelas Khusus | U4: Jumlah Alokasi Tempat Tidur Awal Bulan
A5: 1 | B5: Umum | C5: ='2024-09'!M5 -> 17 | D5: 116 | E5: 7 | F5: 4 | G5: 120 | H5: 0 | I5: 0 | J5: 0 | K5: 0 | L5: 459 | M5: =C5+D5+E5-F5-G5-H5-I5-J5-K5 -> 16 | N5: =SUM(O5:T5) -> 489 | O5: 0 | P5: 10 | Q5: 39 | R5: 88 | S5: 332 | T5: 20 | U5: 24
A6: 2 | B6: Penyakit Dalam | C6: ='2024-09'!M6 -> 14 | D6: 77 | E6: 6 | F6: 4 | G6: 79 | H6: 0 | I6: 0 | J6: 0 | K6: 0 | L6: 364 | M6: =C6+D6+E6-F6-G6-H6-I6-J6-K6 -> 14 | N6: =SUM(O6:T6) -> 402 | O6: 0 | P6: 8 | Q6: 40 | R6: 81 | S6: 249 | T6: 24 | U6: 20
A7: 3 | B7: Kesehatan Anak | C7: ='2024-09'!M7 -> 7 | D7: 61 | E7: 4 | F7: 2 | G7: 62 | H7: 0 | I7: 0 | J7: 0 | K7: 0 | L7: 223 | M7: =C7+D7+E7-F7-G7-H7-I7-J7-K7 -> 8 | N7: =SUM(O7:T7) -> 232 | O7: 0 | P7: 5 | Q7: 23 | R7: 46 | S7: 144 | T7: 14 | U7: 12
A8: 4 | B8: Kesehatan Remaja | C8: ='2024-09'!M8 -> 2 | D8: 13 | E8: 1 | F8: 1 | G8: 13 | H8: 0 | I8: 0 | J8: 0 | K8: 0 | L8: 48 | M8: =C8+D8+E8-F8-G8-H8-I8-J8-K8 -> 2 | N8: =SUM(O8:T8) -> 53 | O8: 0 | P8: 1 | Q8: 5 | R8: 11 | S8: 33 | T8: 3 | U8: 4
A9: 5 | B9: Obstetri | C9: ='2024-09'!M9 -> 10 | D9: 91 | E9: 5 | F9: 4 | G9: 92 | H9: 0 | I9: 0 | J9: 0 | K9: 0 | L9: 277 | M9: =C9+D9+E9-F9-G9-H9-I9-J9-K9 -> 10 | N9: =SUM(O9:T9) -> 294 | O9: 0 | P9: 9 | Q9: 35 | R9: 73 | S9: 171 | T9: 6 | U9: 14
A10: 6 | B10: Ginekologi | C10: ='2024-09'!M10 -> 3 | D10: 22 | E10: 1 | F10: 1 | G10: 21 | H10: 0 | I10: 1 | J10: 0 | K10: 0 | L10: 93 | M10: =C10+D10+E10-F10-G10-H10-I10-J10-K10 -> 3 | N10: =SUM(O10:T10) -> 101 | O10: 0 | P10: 2 | Q10: 10 | R10: 20 | S10: 63 | T10: 6 | U10: 6
A11: 7 | B11: Bedah | C11: ='2024-09'!M11 -> 9 | D11: 51 | E11: 3 | F11: 3 | G11: 49 | H11: 1 | I11: 0 | J11: 0 | K11: 1 | L11: 248 | M11: =C11+D11+E11-F11-G11-H11-I11-J11-K11 -> 9 | N11: =SUM(O11:T11) -> 258 | O11: 0 | P11: 8 | Q11: 31 | R11: 57 | S11: 155 | T11: 7 | U11: 14
A12: 8 | B12: Bedah Orthopedi | C12: ='2024-09'!M12 -> 5 | D12: 20 | E12: 1 | F12: 1 | G12: 20 | H12: 0 | I12: 0 | J12: 0 | K12: 0 | L12: 126 | M12: =C12+D12+E12-F12-G12-H12-I12-J12-K12 -> 5 | N12: =SUM(O12:T12) -> 134 | O12: 0 | P12: 4 | Q12: 16 | R12: 30 | S12: 80 | T12: 4 | U12: 8
A13: 9 | B13: Bedah Saraf | C13: ='2024-09'!M13 -> 2 | D13: 8 | E13: 1 | F13: 1 | G13: 8 | H13: 0 | I13: 0 | J13: 0 | K13: 0 | L13: 63 | M13: =C13+D13+E13-F13-G13-H13-I13-J13-K13 -> 2 | N13: =SUM(O13:T13) -> 65 | O13: 0 | P13: 2 | Q13: 8 | R13: 14 | S13: 39 | T13: 2 | U13: 4
A14: 10 | B14: Luka Bakar | C14: ='2024-09'!M14 -> 0 | D14: 0 | E14: 0 | F14: 0 | G14: 0 | H14: 0 | I14: 0 | J14: 0 | K14: 0 | L14: 0 | M14: =C14+D14+E14-F14-G14-H14-I14-J14-K14 -> 0 | N14: =SUM(O14:T14) -> 0 | O14: 0 | P14: 0 | Q14: 0 | R14: 0 | S14: 0 | T14: 0 | U14: 0
A15: 11 | B15: Saraf | C15: ='2024-09'!M15 -> 0 | D15: 0 | E15: 0 | F15: 0 | G15: 0 | H15: 0 | I15: 0 | J15: 0 | K15: 0 | L15: 0 | M15: =C15+D15+E15-F15-G15-H15-I15-J15-K15 -> 0 | N15: =SUM(O15:T15) -> 0 | O15: 0 | P15: 0 | Q15: 0 | R15: 0 | S15: 0 | T15: 0 | U15: 0
A16: 12 | B16: Jiwa | C16: ='2024-09'!M16 -> 0 | D16: 0 | E16: 0 | F16: 0 | G16: 0 | H16: 0 | I16: 0 | J16: 0 | K16: 0 | L16: 0 | M16: =C16+D16+E16-F16-G16-H16-I16-J16-K16 -> 0 | N16: =SUM(O16:T16) -> 0 | O16: 0 | P16: 0 | Q16: 0 | R16: 0 | S16: 0 | T16: 0 | U16: 0
... A40: 36 | B40: Perinatologi | C40: ='2024-09'!M40 -> 4 | D40: 17 | E40: 3 | F40: 3 | G40: 17 | H40: 0 | I40: 0 | J40: 0 | K40: 0 | L40: 107 | M40: =C40+D40+E40-F40-G40-H40-I40-J40-K40 -> 4 | N40: =SUM(O40:T40) -> 118 | O40: 0 | P40: 0 | Q40: 0 | R40: 6 | S40: 29 | T40: 83 | U40: 6
A41: 99 | B41: TOTAL | C41: =SUM(C5:C40) -> 125 | D41: =SUM(D5:D40) -> 770 | E41: =SUM(E5:E40) -> 88 | F41: =SUM(F5:F40) -> 85 | G41: =SUM(G5:G40) -> 769 | H41: =SUM(H5:H40) -> 2 | I41: =SUM(I5:I40) -> 3 | J41: =SUM(J5:J40) -> 0 | ... U41: =SUM(U5:U40) -> 196

Sheet 2024-11
A1: RL 3.2 - Rekapitulasi Kegiatan Pelayanan Rawat Inap - November 2024
A2: RS Umum Demo Basangdata (fiktif) | DEMO: sandbox latihan input SIRS. Bukan aplikasi resmi Kemenkes.
A4: No | B4: Jenis Pelayanan | C4: Pasien Awal Bulan | D4: Pasien Masuk | E4: Pasien Pindahan | F4: Pasien Dipindahkan | G4: Pasien Keluar Hidup | H4: Pasien Laki-Laki Keluar Mati < 48 jam | I4: Pasien Laki-Laki Keluar Mati ≥ 48 jam | J4: Pasien Perempuan Keluar Mati < 48 jam | K4: Pasien Perempuan Keluar Mati ≥ 48 jam | L4: Jumlah Lama Dirawat | M4: Pasien Akhir Bulan (otomatis) | N4: Jumlah Hari Perawatan (otomatis) | O4: Hari Perawatan Kelas VVIP | P4: Hari Perawatan Kelas VIP | Q4: Hari Perawatan Kelas I | R4: Hari Perawatan Kelas II | S4: Hari Perawatan Kelas III | T4: Hari Perawatan Kelas Khusus | U4: Jumlah Alokasi Tempat Tidur Awal Bulan
A5: 1 | B5: Umum | C5: ='2024-10'!M5 -> 16 | D5: 112 | E5: 6 | F5: 4 | G5: 113 | H5: 0 | I5: 0 | J5: 0 | K5: 0 | L5: 478 | M5: =C5+D5+E5-F5-G5-H5-I5-J5-K5 -> 17 | N5: =SUM(O5:T5) -> 498 | O5: 0 | P5: 10 | Q5: 40 | R5: 89 | S5: 339 | T5: 20 | U5: 24
A6: 2 | B6: Penyakit Dalam | C6: ='2024-10'!M6 -> 14 | D6: 75 | E6: 6 | F6: 4 | G6: 75 | H6: 0 | I6: 1 | J6: 0 | K6: 0 | L6: 367 | M6: =C6+D6+E6-F6-G6-H6-I6-J6-K6 -> 15 | N6: =SUM(O6:T6) -> 392 | O6: 0 | P6: 8 | Q6: 39 | R6: 78 | S6: 243 | T6: 24 | U6: 20
A7: 3 | B7: Kesehatan Anak | C7: ='2024-10'!M7 -> 8 | D7: 60 | E7: 4 | F7: 3 | G7: 61 | H7: 0 | I7: 0 | J7: 0 | K7: 0 | L7: 223 | M7: =C7+D7+E7-F7-G7-H7-I7-J7-K7 -> 8 | N7: =SUM(O7:T7) -> 245 | O7: 0 | P7: 5 | Q7: 24 | R7: 49 | S7: 152 | T7: 15 | U7: 12
A8: 4 | B8: Kesehatan Remaja | C8: ='2024-10'!M8 -> 2 | D8: 12 | E8: 1 | F8: 0 | G8: 13 | H8: 0 | I8: 0 | J8: 0 | K8: 0 | L8: 50 | M8: =C8+D8+E8-F8-G8-H8-I8-J8-K8 -> 2 | N8: =SUM(O8:T8) -> 54 | O8: 0 | P8: 1 | Q8: 5 | R8: 11 | S8: 34 | T8: 3 | U8: 4
A9: 5 | B9: Obstetri | C9: ='2024-10'!M9 -> 10 | D9: 88 | E9: 4 | F9: 4 | G9: 87 | H9: 0 | I9: 0 | J9: 0 | K9: 0 | L9: 273 | M9: =C9+D9+E9-F9-G9-H9-I9-J9-K9 -> 11 | N9: =SUM(O9:T9) -> 293 | O9: 0 | P9: 9 | Q9: 35 | R9: 73 | S9: 170 | T9: 6 | U9: 14
A10: 6 | B10: Ginekologi | C10: ='2024-10'!M10 -> 3 | D10: 23 | E10: 1 | F10: 1 | G10: 23 | H10: 0 | I10: 0 | J10: 0 | K10: 0 | L10: 92 | M10: =C10+D10+E10-F10-G10-H10-I10-J10-K10 -> 3 | N10: =SUM(O10:T10) -> 99 | O10: 0 | P10: 2 | Q10: 10 | R10: 20 | S10: 61 | T10: 6 | U10: 6
A11: 7 | B11: Bedah | C11: ='2024-10'!M11 -> 9 | D11: 52 | E11: 3 | F11: 3 | G11: 52 | H11: 0 | I11: 0 | J11: 0 | K11: 0 | L11: 243 | M11: =C11+D11+E11-F11-G11-H11-I11-J11-K11 -> 9 | N11: =SUM(O11:T11) -> 266 | O11: 0 | P11: 8 | Q11: 32 | R11: 58 | S11: 160 | T11: 8 | U11: 14
A12: 8 | B12: Bedah Orthopedi | C12: ='2024-10'!M12 -> 5 | D12: 19 | E12: 1 | F12: 1 | G12: 19 | H12: 0 | I12: 0 | J12: 0 | K12: 0 | L12: 117 | M12: =C12+D12+E12-F12-G12-H12-I12-J12-K12 -> 5 | N12: =SUM(O12:T12) -> 129 | O12: 0 | P12: 4 | Q12: 16 | R12: 28 | S12: 77 | T12: 4 | U12: 8
A13: 9 | B13: Bedah Saraf | C13: ='2024-10'!M13 -> 2 | D13: 8 | E13: 1 | F13: 1 | G13: 8 | H13: 0 | I13: 0 | J13: 0 | K13: 0 | L13: 65 | M13: =C13+D13+E13-F13-G13-H13-I13-J13-K13 -> 2 | N13: =SUM(O13:T13) -> 68 | O13: 0 | P13: 2 | Q13: 8 | R13: 15 | S13: 41 | T13: 2 | U13: 4
A14: 10 | B14: Luka Bakar | C14: ='2024-10'!M14 -> 0 | D14: 0 | E14: 0 | F14: 0 | G14: 0 | H14: 0 | I14: 0 | J14: 0 | K14: 0 | L14: 0 | M14: =C14+D14+E14-F14-G14-H14-I14-J14-K14 -> 0 | N14: =SUM(O14:T14) -> 0 | O14: 0 | P14: 0 | Q14: 0 | R14: 0 | S14: 0 | T14: 0 | U14: 0
A15: 11 | B15: Saraf | C15: ='2024-10'!M15 -> 0 | D15: 0 | E15: 0 | F15: 0 | G15: 0 | H15: 0 | I15: 0 | J15: 0 | K15: 0 | L15: 0 | M15: =C15+D15+E15-F15-G15-H15-I15-J15-K15 -> 0 | N15: =SUM(O15:T15) -> 0 | O15: 0 | P15: 0 | Q15: 0 | R15: 0 | S15: 0 | T15: 0 | U15: 0
A16: 12 | B16: Jiwa | C16: ='2024-10'!M16 -> 0 | D16: 0 | E16: 0 | F16: 0 | G16: 0 | H16: 0 | I16: 0 | J16: 0 | K16: 0 | L16: 0 | M16: =C16+D16+E16-F16-G16-H16-I16-J16-K16 -> 0 | N16: =SUM(O16:T16) -> 0 | O16: 0 | P16: 0 | Q16: 0 | R16: 0 | S16: 0 | T16: 0 | U16: 0
... A40: 36 | B40: Perinatologi | C40: ='2024-10'!M40 -> 4 | D40: 20 | E40: 3 | F40: 3 | G40: 19 | H40: 0 | I40: 1 | J40: 0 | K40: 0 | L40: 115 | M40: =C40+D40+E40-F40-G40-H40-I40-J40-K40 -> 4 | N40: =SUM(O40:T40) -> 123 | O40: 0 | P40: 0 | Q40: 0 | R40: 6 | S40: 31 | T40: 86 | U40: 6
A41: 99 | B41: TOTAL | C41: =SUM(C5:C40) -> 122 | D41: =SUM(D5:D40) -> 768 | E41: =SUM(E5:E40) -> 83 | F41: =SUM(F5:F40) -> 81 | G41: =SUM(G5:G40) -> 755 | H41: =SUM(H5:H40) -> 2 | I41: =SUM(I5:I40) -> 6 | J41: =SUM(J5:J40) -> 0 | ... U41: =SUM(U5:U40) -> 196

Sheet 2024-12
A1: RL 3.2 - Rekapitulasi Kegiatan Pelayanan Rawat Inap - Desember 2024
A2: RS Umum Demo Basangdata (fiktif) | DEMO: sandbox latihan input SIRS. Bukan aplikasi resmi Kemenkes.
A4: No | B4: Jenis Pelayanan | C4: Pasien Awal Bulan | D4: Pasien Masuk | E4: Pasien Pindahan | F4: Pasien Dipindahkan | G4: Pasien Keluar Hidup | H4: Pasien Laki-Laki Keluar Mati < 48 jam | I4: Pasien Laki-Laki Keluar Mati ≥ 48 jam | J4: Pasien Perempuan Keluar Mati < 48 jam | K4: Pasien Perempuan Keluar Mati ≥ 48 jam | L4: Jumlah Lama Dirawat | M4: Pasien Akhir Bulan (otomatis) | N4: Jumlah Hari Perawatan (otomatis) | O4: Hari Perawatan Kelas VVIP | P4: Hari Perawatan Kelas VIP | Q4: Hari Perawatan Kelas I | R4: Hari Perawatan Kelas II | S4: Hari Perawatan Kelas III | T4: Hari Perawatan Kelas Khusus | U4: Jumlah Alokasi Tempat Tidur Awal Bulan
A5: 1 | B5: Umum | C5: ='2024-11'!M5 -> 17 | D5: 108 | E5: 7 | F5: 5 | G5: 110 | H5: 0 | I5: 1 | J5: 0 | K5: 0 | L5: 489 | M5: =C5+D5+E5-F5-G5-H5-I5-J5-K5 -> 16 | N5: =SUM(O5:T5) -> 504 | O5: 0 | P5: 10 | Q5: 40 | R5: 91 | S5: 343 | T5: 20 | U5: 24
A6: 2 | B6: Penyakit Dalam | C6: ='2024-11'!M6 -> 15 | D6: 83 | E6: 6 | F6: 5 | G6: 84 | H6: 0 | I6: 1 | J6: 0 | K6: 0 | L6: 404 | M6: =C6+D6+E6-F6-G6-H6-I6-J6-K6 -> 14 | N6: =SUM(O6:T6) -> 425 | O6: 0 | P6: 9 | Q6: 43 | R6: 85 | S6: 263 | T6: 25 | U6: 20
A7: 3 | B7: Kesehatan Anak | C7: ='2024-11'!M7 -> 8 | D7: 61 | E7: 4 | F7: 2 | G7: 63 | H7: 0 | I7: 1 | J7: 0 | K7: 0 | L7: 229 | M7: =C7+D7+E7-F7-G7-H7-I7-J7-K7 -> 7 | N7: =SUM(O7:T7) -> 242 | O7: 0 | P7: 5 | Q7: 24 | R7: 48 | S7: 150 | T7: 15 | U7: 12
A8: 4 | B8: Kesehatan Remaja | C8: ='2024-11'!M8 -> 2 | D8: 15 | E8: 1 | F8: 1 | G8: 15 | H8: 0 | I8: 0 | J8: 0 | K8: 0 | L8: 53 | M8: =C8+D8+E8-F8-G8-H8-I8-J8-K8 -> 2 | N8: =SUM(O8:T8) -> 58 | O8: 0 | P8: 1 | Q8: 6 | R8: 12 | S8: 36 | T8: 3 | U8: 4
A9: 5 | B9: Obstetri | C9: ='2024-11'!M9 -> 11 | D9: 99 | E9: 5 | F9: 4 | G9: 102 | H9: 0 | I9: 0 | J9: 0 | K9: 0 | L9: 301 | M9: =C9+D9+E9-F9-G9-H9-I9-J9-K9 -> 9 | N9: =SUM(O9:T9) -> 317 | O9: 0 | P9: 10 | Q9: 38 | R9: 79 | S9: 184 | T9: 6 | U9: 14
A10: 6 | B10: Ginekologi | C10: ='2024-11'!M10 -> 3 | D10: 22 | E10: 1 | F10: 1 | G10: 21 | H10: 0 | I10: 1 | J10: 0 | K10: 0 | L10: 93 | M10: =C10+D10+E10-F10-G10-H10-I10-J10-K10 -> 3 | N10: =SUM(O10:T10) -> 103 | O10: 0 | P10: 2 | Q10: 10 | R10: 21 | S10: 64 | T10: 6 | U10: 6
A11: 7 | B11: Bedah | C11: ='2024-11'!M11 -> 9 | D11: 55 | E11: 3 | F11: 2 | G11: 56 | H11: 0 | I11: 0 | J11: 0 | K11: 0 | L11: 248 | M11: =C11+D11+E11-F11-G11-H11-I11-J11-K11 -> 9 | N11: =SUM(O11:T11) -> 273 | O11: 0 | P11: 8 | Q11: 33 | R11: 60 | S11: 164 | T11: 8 | U11: 14
A12: 8 | B12: Bedah Orthopedi | C12: ='2024-11'!M12 -> 5 | D12: 19 | E12: 1 | F12: 1 | G12: 20 | H12: 0 | I12: 0 | J12: 0 | K12: 0 | L12: 127 | M12: =C12+D12+E12-F12-G12-H12-I12-J12-K12 -> 4 | N12: =SUM(O12:T12) -> 139 | O12: 0 | P12: 4 | Q12: 17 | R12: 31 | S12: 83 | T12: 4 | U12: 8
A13: 9 | B13: Bedah Saraf | C13: ='2024-11'!M13 -> 2 | D13: 9 | E13: 1 | F13: 1 | G13: 9 | H13: 0 | I13: 0 | J13: 0 | K13: 0 | L13: 68 | M13: =C13+D13+E13-F13-G13-H13-I13-J13-K13 -> 2 | N13: =SUM(O13:T13) -> 72 | O13: 0 | P13: 2 | Q13: 9 | R13: 16 | S13: 43 | T13: 2 | U13: 4
A14: 10 | B14: Luka Bakar | C14: ='2024-11'!M14 -> 0 | D14: 0 | E14: 0 | F14: 0 | G14: 0 | H14: 0 | I14: 0 | J14: 0 | K14: 0 | L14: 0 | M14: =C14+D14+E14-F14-G14-H14-I14-J14-K14 -> 0 | N14: =SUM(O14:T14) -> 0 | O14: 0 | P14: 0 | Q14: 0 | R14: 0 | S14: 0 | T14: 0 | U14: 0
A15: 11 | B15: Saraf | C15: ='2024-11'!M15 -> 0 | D15: 0 | E15: 0 | F15: 0 | G15: 0 | H15: 0 | I15: 0 | J15: 0 | K15: 0 | L15: 0 | M15: =C15+D15+E15-F15-G15-H15-I15-J15-K15 -> 0 | N15: =SUM(O15:T15) -> 0 | O15: 0 | P15: 0 | Q15: 0 | R15: 0 | S15: 0 | T15: 0 | U15: 0
A16: 12 | B16: Jiwa | C16: ='2024-11'!M16 -> 0 | D16: 0 | E16: 0 | F16: 0 | G16: 0 | H16: 0 | I16: 0 | J16: 0 | K16: 0 | L16: 0 | M16: =C16+D16+E16-F16-G16-H16-I16-J16-K16 -> 0 | N16: =SUM(O16:T16) -> 0 | O16: 0 | P16: 0 | Q16: 0 | R16: 0 | S16: 0 | T16: 0 | U16: 0
... A40: 36 | B40: Perinatologi | C40: ='2024-11'!M40 -> 4 | D40: 21 | E40: 4 | F40: 3 | G40: 21 | H40: 0 | I40: 1 | J40: 0 | K40: 0 | L40: 127 | M40: =C40+D40+E40-F40-G40-H40-I40-J40-K40 -> 4 | N40: =SUM(O40:T40) -> 136 | O40: 0 | P40: 0 | Q40: 0 | R40: 7 | S40: 34 | T40: 95 | U40: 6
A41: 99 | B41: TOTAL | C41: =SUM(C5:C40) -> 127 | D41: =SUM(D5:D40) -> 813 | E41: =SUM(E5:E40) -> 88 | F41: =SUM(F5:F40) -> 91 | G41: =SUM(G5:G40) -> 804 | H41: =SUM(H5:H40) -> 1 | I41: =SUM(I5:I40) -> 10 | J41: =SUM(J5:J40) -> 0 | ... U41: =SUM(U5:U40) -> 196

Sheet 2025-01
A1: RL 3.2 - Rekapitulasi Kegiatan Pelayanan Rawat Inap - Januari 2025
A2: RS Umum Demo Basangdata (fiktif) | DEMO: sandbox latihan input SIRS. Bukan aplikasi resmi Kemenkes.
A4: No | B4: Jenis Pelayanan | C4: Pasien Awal Bulan | D4: Pasien Masuk | E4: Pasien Pindahan | F4: Pasien Dipindahkan | G4: Pasien Keluar Hidup | H4: Pasien Laki-Laki Keluar Mati < 48 jam | I4: Pasien Laki-Laki Keluar Mati ≥ 48 jam | J4: Pasien Perempuan Keluar Mati < 48 jam | K4: Pasien Perempuan Keluar Mati ≥ 48 jam | L4: Jumlah Lama Dirawat | M4: Pasien Akhir Bulan (otomatis) | N4: Jumlah Hari Perawatan (otomatis) | O4: Hari Perawatan Kelas VVIP | P4: Hari Perawatan Kelas VIP | Q4: Hari Perawatan Kelas I | R4: Hari Perawatan Kelas II | S4: Hari Perawatan Kelas III | T4: Hari Perawatan Kelas Khusus | U4: Jumlah Alokasi Tempat Tidur Awal Bulan
A5: 1 | B5: Umum | C5: ='2024-12'!M5 -> 16 | D5: 109 | E5: 8 | F5: 5 | G5: 111 | H5: 1 | I5: 0 | J5: 0 | K5: 1 | L5: 478 | M5: =C5+D5+E5-F5-G5-H5-I5-J5-K5 -> 15 | N5: =SUM(O5:T5) -> 513 | O5: 0 | P5: 10 | Q5: 41 | R5: 92 | S5: 349 | T5: 21 | U5: 24
A6: 2 | B6: Penyakit Dalam | C6: ='2024-12'!M6 -> 14 | D6: 93 | E6: 7 | F6: 5 | G6: 92 | H6: 1 | I6: 0 | J6: 0 | K6: 1 | L6: 437 | M6: =C6+D6+E6-F6-G6-H6-I6-J6-K6 -> 15 | N6: =SUM(O6:T6) -> 480 | O6: 0 | P6: 9 | Q6: 48 | R6: 96 | S6: 298 | T6: 29 | U6: 20
A7: 3 | B7: Kesehatan Anak | C7: ='2024-12'!M7 -> 7 | D7: 62 | E7: 4 | F7: 3 | G7: 61 | H7: 0 | I7: 0 | J7: 0 | K7: 0 | L7: 249 | M7: =C7+D7+E7-F7-G7-H7-I7-J7-K7 -> 9 | N7: =SUM(O7:T7) -> 262 | O7: 0 | P7: 5 | Q7: 26 | R7: 52 | S7: 163 | T7: 16 | U7: 12
A8: 4 | B8: Kesehatan Remaja | C8: ='2024-12'!M8 -> 2 | D8: 14 | E8: 1 | F8: 1 | G8: 14 | H8: 0 | I8: 0 | J8: 0 | K8: 0 | L8: 53 | M8: =C8+D8+E8-F8-G8-H8-I8-J8-K8 -> 2 | N8: =SUM(O8:T8) -> 57 | O8: 0 | P8: 1 | Q8: 6 | R8: 11 | S8: 35 | T8: 4 | U8: 4
A9: 5 | B9: Obstetri | C9: ='2024-12'!M9 -> 9 | D9: 105 | E9: 6 | F9: 4 | G9: 105 | H9: 0 | I9: 1 | J9: 0 | K9: 0 | L9: 297 | M9: =C9+D9+E9-F9-G9-H9-I9-J9-K9 -> 10 | N9: =SUM(O9:T9) -> 319 | O9: 0 | P9: 10 | Q9: 38 | R9: 80 | S9: 185 | T9: 6 | U9: 14
A10: 6 | B10: Ginekologi | C10: ='2024-12'!M10 -> 3 | D10: 23 | E10: 1 | F10: 1 | G10: 22 | H10: 0 | I10: 1 | J10: 0 | K10: 0 | L10: 99 | M10: =C10+D10+E10-F10-G10-H10-I10-J10-K10 -> 3 | N10: =SUM(O10:T10) -> 105 | O10: 0 | P10: 2 | Q10: 11 | R10: 21 | S10: 65 | T10: 6 | U10: 6
A11: 7 | B11: Bedah | C11: ='2024-12'!M11 -> 9 | D11: 53 | E11: 3 | F11: 3 | G11: 53 | H11: 0 | I11: 0 | J11: 0 | K11: 0 | L11: 255 | M11: =C11+D11+E11-F11-G11-H11-I11-J11-K11 -> 9 | N11: =SUM(O11:T11) -> 274 | O11: 0 | P11: 8 | Q11: 33 | R11: 60 | S11: 165 | T11: 8 | U11: 14
A12: 8 | B12: Bedah Orthopedi | C12: ='2024-12'!M12 -> 4 | D12: 21 | E12: 1 | F12: 1 | G12: 20 | H12: 0 | I12: 0 | J12: 0 | K12: 0 | L12: 144 | M12: =C12+D12+E12-F12-G12-H12-I12-J12-K12 -> 5 | N12: =SUM(O12:T12) -> 154 | O12: 0 | P12: 5 | Q12: 18 | R12: 34 | S12: 92 | T12: 5 | U12: 8
A13: 9 | B13: Bedah Saraf | C13: ='2024-12'!M13 -> 2 | D13: 9 | E13: 1 | F13: 1 | G13: 7 | H13: 1 | I13: 0 | J13: 0 | K13: 1 | L13: 62 | M13: =C13+D13+E13-F13-G13-H13-I13-J13-K13 -> 2 | N13: =SUM(O13:T13) -> 69 | O13: 0 | P13: 2 | Q13: 8 | R13: 15 | S13: 42 | T13: 2 | U13: 4
A14: 10 | B14: Luka Bakar | C14: ='2024-12'!M14 -> 0 | D14: 0 | E14: 0 | F14: 0 | G14: 0 | H14: 0 | I14: 0 | J14: 0 | K14: 0 | L14: 0 | M14: =C14+D14+E14-F14-G14-H14-I14-J14-K14 -> 0 | N14: =SUM(O14:T14) -> 0 | O14: 0 | P14: 0 | Q14: 0 | R14: 0 | S14: 0 | T14: 0 | U14: 0
A15: 11 | B15: Saraf | C15: ='2024-12'!M15 -> 0 | D15: 0 | E15: 0 | F15: 0 | G15: 0 | H15: 0 | I15: 0 | J15: 0 | K15: 0 | L15: 0 | M15: =C15+D15+E15-F15-G15-H15-I15-J15-K15 -> 0 | N15: =SUM(O15:T15) -> 0 | O15: 0 | P15: 0 | Q15: 0 | R15: 0 | S15: 0 | T15: 0 | U15: 0
A16: 12 | B16: Jiwa | C16: ='2024-12'!M16 -> 0 | D16: 0 | E16: 0 | F16: 0 | G16: 0 | H16: 0 | I16: 0 | J16: 0 | K16: 0 | L16: 0 | M16: =C16+D16+E16-F16-G16-H16-I16-J16-K16 -> 0 | N16: =SUM(O16:T16) -> 0 | O16: 0 | P16: 0 | Q16: 0 | R16: 0 | S16: 0 | T16: 0 | U16: 0
... A40: 36 | B40: Perinatologi | C40: ='2024-12'!M40 -> 4 | D40: 20 | E40: 3 | F40: 3 | G40: 18 | H40: 1 | I40: 0 | J40: 0 | K40: 1 | L40: 130 | M40: =C40+D40+E40-F40-G40-H40-I40-J40-K40 -> 4 | N40: =SUM(O40:T40) -> 138 | O40: 0 | P40: 0 | Q40: 0 | R40: 7 | S40: 34 | T40: 97 | U40: 6
A41: 99 | B41: TOTAL | C41: =SUM(C5:C40) -> 121 | D41: =SUM(D5:D40) -> 839 | E41: =SUM(E5:E40) -> 98 | F41: =SUM(F5:F40) -> 89 | G41: =SUM(G5:G40) -> 829 | H41: =SUM(H5:H40) -> 5 | I41: =SUM(I5:I40) -> 5 | J41: =SUM(J5:J40) -> 0 | ... U41: =SUM(U5:U40) -> 196

Sheet 2025-02
A1: RL 3.2 - Rekapitulasi Kegiatan Pelayanan Rawat Inap - Februari 2025
A2: RS Umum Demo Basangdata (fiktif) | DEMO: sandbox latihan input SIRS. Bukan aplikasi resmi Kemenkes.
A4: No | B4: Jenis Pelayanan | C4: Pasien Awal Bulan | D4: Pasien Masuk | E4: Pasien Pindahan | F4: Pasien Dipindahkan | G4: Pasien Keluar Hidup | H4: Pasien Laki-Laki Keluar Mati < 48 jam | I4: Pasien Laki-Laki Keluar Mati ≥ 48 jam | J4: Pasien Perempuan Keluar Mati < 48 jam | K4: Pasien Perempuan Keluar Mati ≥ 48 jam | L4: Jumlah Lama Dirawat | M4: Pasien Akhir Bulan (otomatis) | N4: Jumlah Hari Perawatan (otomatis) | O4: Hari Perawatan Kelas VVIP | P4: Hari Perawatan Kelas VIP | Q4: Hari Perawatan Kelas I | R4: Hari Perawatan Kelas II | S4: Hari Perawatan Kelas III | T4: Hari Perawatan Kelas Khusus | U4: Jumlah Alokasi Tempat Tidur Awal Bulan
A5: 1 | B5: Umum | C5: ='2025-01'!M5 -> 15 | D5: 105 | E5: 7 | F5: 5 | G5: 103 | H5: 1 | I5: 0 | J5: 0 | K5: 1 | L5: 459 | M5: =C5+D5+E5-F5-G5-H5-I5-J5-K5 -> 17 | N5: =SUM(O5:T5) -> 488 | O5: 0 | P5: 10 | Q5: 39 | R5: 88 | S5: 332 | T5: 19 | U5: 24
A6: 2 | B6: Penyakit Dalam | C6: ='2025-01'!M6 -> 15 | D6: 79 | E6: 6 | F6: 4 | G6: 81 | H6: 1 | I6: 0 | J6: 0 | K6: 1 | L6: 394 | M6: =C6+D6+E6-F6-G6-H6-I6-J6-K6 -> 13 | N6: =SUM(O6:T6) -> 420 | O6: 0 | P6: 9 | Q6: 42 | R6: 84 | S6: 260 | T6: 25 | U6: 20
A7: 3 | B7: Kesehatan Anak | C7: ='2025-01'!M7 -> 9 | D7: 61 | E7: 4 | F7: 2 | G7: 64 | H7: 0 | I7: 1 | J7: 0 | K7: 0 | L7: 223 | M7: =C7+D7+E7-F7-G7-H7-I7-J7-K7 -> 7 | N7: =SUM(O7:T7) -> 244 | O7: 0 | P7: 5 | Q7: 24 | R7: 49 | S7: 151 | T7: 15 | U7: 12
A8: 4 | B8: Kesehatan Remaja | C8: ='2025-01'!M8 -> 2 | D8: 14 | E8: 1 | F8: 1 | G8: 14 | H8: 0 | I8: 0 | J8: 0 | K8: 0 | L8: 52 | M8: =C8+D8+E8-F8-G8-H8-I8-J8-K8 -> 2 | N8: =SUM(O8:T8) -> 56 | O8: 0 | P8: 1 | Q8: 6 | R8: 11 | S8: 35 | T8: 3 | U8: 4
A9: 5 | B9: Obstetri | C9: ='2025-01'!M9 -> 10 | D9: 91 | E9: 5 | F9: 4 | G9: 90 | H9: 0 | I9: 1 | J9: 0 | K9: 0 | L9: 283 | M9: =C9+D9+E9-F9-G9-H9-I9-J9-K9 -> 11 | N9: =SUM(O9:T9) -> 305 | O9: 0 | P9: 9 | Q9: 37 | R9: 76 | S9: 177 | T9: 6 | U9: 14
A10: 6 | B10: Ginekologi | C10: ='2025-01'!M10 -> 3 | D10: 21 | E10: 1 | F10: 1 | G10: 20 | H10: 0 | I10: 1 | J10: 0 | K10: 0 | L10: 88 | M10: =C10+D10+E10-F10-G10-H10-I10-J10-K10 -> 3 | N10: =SUM(O10:T10) -> 94 | O10: 0 | P10: 2 | Q10: 9 | R10: 19 | S10: 58 | T10: 6 | U10: 6
A11: 7 | B11: Bedah | C11: ='2025-01'!M11 -> 9 | D11: 51 | E11: 4 | F11: 3 | G11: 51 | H11: 0 | I11: 1 | J11: 0 | K11: 0 | L11: 248 | M11: =C11+D11+E11-F11-G11-H11-I11-J11-K11 -> 9 | N11: =SUM(O11:T11) -> 268 | O11: 0 | P11: 8 | Q11: 32 | R11: 59 | S11: 161 | T11: 8 | U11: 14
A12: 8 | B12: Bedah Orthopedi | C12: ='2025-01'!M12 -> 5 | D12: 21 | E12: 1 | F12: 1 | G12: 21 | H12: 0 | I12: 0 | J12: 0 | K12: 0 | L12: 131 | M12: =C12+D12+E12-F12-G12-H12-I12-J12-K12 -> 5 | N12: =SUM(O12:T12) -> 140 | O12: 0 | P12: 4 | Q12: 17 | R12: 31 | S12: 84 | T12: 4 | U12: 8
A13: 9 | B13: Bedah Saraf | C13: ='2025-01'!M13 -> 2 | D13: 9 | E13: 1 | F13: 1 | G13: 9 | H13: 0 | I13: 0 | J13: 0 | K13: 0 | L13: 63 | M13: =C13+D13+E13-F13-G13-H13-I13-J13-K13 -> 2 | N13: =SUM(O13:T13) -> 68 | O13: 0 | P13: 2 | Q13: 8 | R13: 15 | S13: 41 | T13: 2 | U13: 4
A14: 10 | B14: Luka Bakar | C14: ='2025-01'!M14 -> 0 | D14: 0 | E14: 0 | F14: 0 | G14: 0 | H14: 0 | I14: 0 | J14: 0 | K14: 0 | L14: 0 | M14: =C14+D14+E14-F14-G14-H14-I14-J14-K14 -> 0 | N14: =SUM(O14:T14) -> 0 | O14: 0 | P14: 0 | Q14: 0 | R14: 0 | S14: 0 | T14: 0 | U14: 0
A15: 11 | B15: Saraf | C15: ='2025-01'!M15 -> 0 | D15: 0 | E15: 0 | F15: 0 | G15: 0 | H15: 0 | I15: 0 | J15: 0 | K15: 0 | L15: 0 | M15: =C15+D15+E15-F15-G15-H15-I15-J15-K15 -> 0 | N15: =SUM(O15:T15) -> 0 | O15: 0 | P15: 0 | Q15: 0 | R15: 0 | S15: 0 | T15: 0 | U15: 0
A16: 12 | B16: Jiwa | C16: ='2025-01'!M16 -> 0 | D16: 0 | E16: 0 | F16: 0 | G16: 0 | H16: 0 | I16: 0 | J16: 0 | K16: 0 | L16: 0 | M16: =C16+D16+E16-F16-G16-H16-I16-J16-K16 -> 0 | N16: =SUM(O16:T16) -> 0 | O16: 0 | P16: 0 | Q16: 0 | R16: 0 | S16: 0 | T16: 0 | U16: 0
... A40: 36 | B40: Perinatologi | C40: ='2025-01'!M40 -> 4 | D40: 19 | E40: 3 | F40: 3 | G40: 18 | H40: 0 | I40: 1 | J40: 0 | K40: 0 | L40: 119 | M40: =C40+D40+E40-F40-G40-H40-I40-J40-K40 -> 4 | N40: =SUM(O40:T40) -> 129 | O40: 0 | P40: 0 | Q40: 0 | R40: 7 | S40: 32 | T40: 90 | U40: 6
A41: 99 | B41: TOTAL | C41: =SUM(C5:C40) -> 125 | D41: =SUM(D5:D40) -> 767 | E41: =SUM(E5:E40) -> 88 | F41: =SUM(F5:F40) -> 85 | G41: =SUM(G5:G40) -> 758 | H41: =SUM(H5:H40) -> 3 | I41: =SUM(I5:I40) -> 9 | J41: =SUM(J5:J40) -> 0 | ... U41: =SUM(U5:U40) -> 196

Sheet 2025-03
A1: RL 3.2 - Rekapitulasi Kegiatan Pelayanan Rawat Inap - Maret 2025
A2: RS Umum Demo Basangdata (fiktif) | DEMO: sandbox latihan input SIRS. Bukan aplikasi resmi Kemenkes.
A4: No | B4: Jenis Pelayanan | C4: Pasien Awal Bulan | D4: Pasien Masuk | E4: Pasien Pindahan | F4: Pasien Dipindahkan | G4: Pasien Keluar Hidup | H4: Pasien Laki-Laki Keluar Mati < 48 jam | I4: Pasien Laki-Laki Keluar Mati ≥ 48 jam | J4: Pasien Perempuan Keluar Mati < 48 jam | K4: Pasien Perempuan Keluar Mati ≥ 48 jam | L4: Jumlah Lama Dirawat | M4: Pasien Akhir Bulan (otomatis) | N4: Jumlah Hari Perawatan (otomatis) | O4: Hari Perawatan Kelas VVIP | P4: Hari Perawatan Kelas VIP | Q4: Hari Perawatan Kelas I | R4: Hari Perawatan Kelas II | S4: Hari Perawatan Kelas III | T4: Hari Perawatan Kelas Khusus | U4: Jumlah Alokasi Tempat Tidur Awal Bulan
A5: 1 | B5: Umum | C5: ='2025-02'!M5 -> 17 | D5: 124 | E5: 8 | F5: 6 | G5: 125 | H5: 0 | I5: 1 | J5: 0 | K5: 0 | L5: 502 | M5: =C5+D5+E5-F5-G5-H5-I5-J5-K5 -> 17 | N5: =SUM(O5:T5) -> 534 | O5: 0 | P5: 11 | Q5: 43 | R5: 96 | S5: 363 | T5: 21 | U5: 24
A6: 2 | B6: Penyakit Dalam | C6: ='2025-02'!M6 -> 13 | D6: 85 | E6: 7 | F6: 5 | G6: 84 | H6: 0 | I6: 1 | J6: 0 | K6: 0 | L6: 417 | M6: =C6+D6+E6-F6-G6-H6-I6-J6-K6 -> 15 | N6: =SUM(O6:T6) -> 440 | O6: 0 | P6: 9 | Q6: 44 | R6: 88 | S6: 273 | T6: 26 | U6: 20
A7: 3 | B7: Kesehatan Anak | C7: ='2025-02'!M7 -> 7 | D7: 71 | E7: 4 | F7: 2 | G7: 70 | H7: 1 | I7: 0 | J7: 0 | K7: 1 | L7: 250 | M7: =C7+D7+E7-F7-G7-H7-I7-J7-K7 -> 8 | N7: =SUM(O7:T7) -> 274 | O7: 0 | P7: 6 | Q7: 27 | R7: 55 | S7: 170 | T7: 16 | U7: 12
A8: 4 | B8: Kesehatan Remaja | C8: ='2025-02'!M8 -> 2 | D8: 14 | E8: 1 | F8: 0 | G8: 15 | H8: 0 | I8: 0 | J8: 0 | K8: 0 | L8: 55 | M8: =C8+D8+E8-F8-G8-H8-I8-J8-K8 -> 2 | N8: =SUM(O8:T8) -> 57 | O8: 0 | P8: 1 | Q8: 6 | R8: 11 | S8: 35 | T8: 4 | U8: 4
A9: 5 | B9: Obstetri | C9: ='2025-02'!M9 -> 11 | D9: 101 | E9: 6 | F9: 5 | G9: 103 | H9: 0 | I9: 0 | J9: 0 | K9: 0 | L9: 308 | M9: =C9+D9+E9-F9-G9-H9-I9-J9-K9 -> 10 | N9: =SUM(O9:T9) -> 334 | O9: 0 | P9: 10 | Q9: 40 | R9: 83 | S9: 194 | T9: 7 | U9: 14
A10: 6 | B10: Ginekologi | C10: ='2025-02'!M10 -> 3 | D10: 24 | E10: 1 | F10: 1 | G10: 24 | H10: 0 | I10: 0 | J10: 0 | K10: 0 | L10: 104 | M10: =C10+D10+E10-F10-G10-H10-I10-J10-K10 -> 3 | N10: =SUM(O10:T10) -> 112 | O10: 0 | P10: 2 | Q10: 11 | R10: 22 | S10: 70 | T10: 7 | U10: 6
A11: 7 | B11: Bedah | C11: ='2025-02'!M11 -> 9 | D11: 53 | E11: 4 | F11: 3 | G11: 53 | H11: 0 | I11: 1 | J11: 0 | K11: 0 | L11: 269 | M11: =C11+D11+E11-F11-G11-H11-I11-J11-K11 -> 9 | N11: =SUM(O11:T11) -> 286 | O11: 0 | P11: 9 | Q11: 34 | R11: 63 | S11: 172 | T11: 8 | U11: 14
A12: 8 | B12: Bedah Orthopedi | C12: ='2025-02'!M12 -> 5 | D12: 22 | E12: 1 | F12: 1 | G12: 22 | H12: 0 | I12: 0 | J12: 0 | K12: 0 | L12: 135 | M12: =C12+D12+E12-F12-G12-H12-I12-J12-K12 -> 5 | N12: =SUM(O12:T12) -> 147 | O12: 0 | P12: 5 | Q12: 18 | R12: 32 | S12: 88 | T12: 4 | U12: 8
A13: 9 | B13: Bedah Saraf | C13: ='2025-02'!M13 -> 2 | D13: 10 | E13: 1 | F13: 1 | G13: 10 | H13: 0 | I13: 0 | J13: 0 | K13: 0 | L13: 73 | M13: =C13+D13+E13-F13-G13-H13-I13-J13-K13 -> 2 | N13: =SUM(O13:T13) -> 77 | O13: 0 | P13: 3 | Q13: 9 | R13: 17 | S13: 46 | T13: 2 | U13: 4
A14: 10 | B14: Luka Bakar | C14: ='2025-02'!M14 -> 0 | D14: 0 | E14: 0 | F14: 0 | G14: 0 | H14: 0 | I14: 0 | J14: 0 | K14: 0 | L14: 0 | M14: =C14+D14+E14-F14-G14-H14-I14-J14-K14 -> 0 | N14: =SUM(O14:T14) -> 0 | O14: 0 | P14: 0 | Q14: 0 | R14: 0 | S14: 0 | T14: 0 | U14: 0
A15: 11 | B15: Saraf | C15: ='2025-02'!M15 -> 0 | D15: 0 | E15: 0 | F15: 0 | G15: 0 | H15: 0 | I15: 0 | J15: 0 | K15: 0 | L15: 0 | M15: =C15+D15+E15-F15-G15-H15-I15-J15-K15 -> 0 | N15: =SUM(O15:T15) -> 0 | O15: 0 | P15: 0 | Q15: 0 | R15: 0 | S15: 0 | T15: 0 | U15: 0
A16: 12 | B16: Jiwa | C16: ='2025-02'!M16 -> 0 | D16: 0 | E16: 0 | F16: 0 | G16: 0 | H16: 0 | I16: 0 | J16: 0 | K16: 0 | L16: 0 | M16: =C16+D16+E16-F16-G16-H16-I16-J16-K16 -> 0 | N16: =SUM(O16:T16) -> 0 | O16: 0 | P16: 0 | Q16: 0 | R16: 0 | S16: 0 | T16: 0 | U16: 0
... A40: 36 | B40: Perinatologi | C40: ='2025-02'!M40 -> 4 | D40: 22 | E40: 3 | F40: 3 | G40: 19 | H40: 1 | I40: 1 | J40: 0 | K40: 1 | L40: 127 | M40: =C40+D40+E40-F40-G40-H40-I40-J40-K40 -> 4 | N40: =SUM(O40:T40) -> 137 | O40: 0 | P40: 0 | Q40: 0 | R40: 7 | S40: 34 | T40: 96 | U40: 6
A41: 99 | B41: TOTAL | C41: =SUM(C5:C40) -> 122 | D41: =SUM(D5:D40) -> 854 | E41: =SUM(E5:E40) -> 96 | F41: =SUM(F5:F40) -> 97 | G41: =SUM(G5:G40) -> 835 | H41: =SUM(H5:H40) -> 3 | I41: =SUM(I5:I40) -> 9 | J41: =SUM(J5:J40) -> 0 | ... U41: =SUM(U5:U40) -> 196

Sheet 2025-04
A1: RL 3.2 - Rekapitulasi Kegiatan Pelayanan Rawat Inap - April 2025
A2: RS Umum Demo Basangdata (fiktif) | DEMO: sandbox latihan input SIRS. Bukan aplikasi resmi Kemenkes.
A4: No | B4: Jenis Pelayanan | C4: Pasien Awal Bulan | D4: Pasien Masuk | E4: Pasien Pindahan | F4: Pasien Dipindahkan | G4: Pasien Keluar Hidup | H4: Pasien Laki-Laki Keluar Mati < 48 jam | I4: Pasien Laki-Laki Keluar Mati ≥ 48 jam | J4: Pasien Perempuan Keluar Mati < 48 jam | K4: Pasien Perempuan Keluar Mati ≥ 48 jam | L4: Jumlah Lama Dirawat | M4: Pasien Akhir Bulan (otomatis) | N4: Jumlah Hari Perawatan (otomatis) | O4: Hari Perawatan Kelas VVIP | P4: Hari Perawatan Kelas VIP | Q4: Hari Perawatan Kelas I | R4: Hari Perawatan Kelas II | S4: Hari Perawatan Kelas III | T4: Hari Perawatan Kelas Khusus | U4: Jumlah Alokasi Tempat Tidur Awal Bulan
A5: 1 | B5: Umum | C5: ='2025-03'!M5 -> 17 | D5: 111 | E5: 8 | F5: 4 | G5: 115 | H5: 0 | I5: 1 | J5: 0 | K5: 0 | L5: 475 | M5: =C5+D5+E5-F5-G5-H5-I5-J5-K5 -> 16 | N5: =SUM(O5:T5) -> 495 | O5: 0 | P5: 10 | Q5: 39 | R5: 89 | S5: 337 | T5: 20 | U5: 24
A6: 2 | B6: Penyakit Dalam | C6: ='2025-03'!M6 -> 15 | D6: 88 | E6: 6 | F6: 5 | G6: 91 | H6: 0 | I6: 0 | J6: 0 | K6: 0 | L6: 404 | M6: =C6+D6+E6-F6-G6-H6-I6-J6-K6 -> 13 | N6: =SUM(O6:T6) -> 441 | O6: 0 | P6: 9 | Q6: 44 | R6: 88 | S6: 273 | T6: 27 | U6: 20
A7: 3 | B7: Kesehatan Anak | C7: ='2025-03'!M7 -> 8 | D7: 59 | E7: 4 | F7: 2 | G7: 60 | H7: 0 | I7: 0 | J7: 0 | K7: 0 | L7: 239 | M7: =C7+D7+E7-F7-G7-H7-I7-J7-K7 -> 9 | N7: =SUM(O7:T7) -> 258 | O7: 0 | P7: 5 | Q7: 26 | R7: 52 | S7: 160 | T7: 15 | U7: 12
A8: 4 | B8: Kesehatan Remaja | C8: ='2025-03'!M8 -> 2 | D8: 14 | E8: 1 | F8: 1 | G8: 14 | H8: 0 | I8: 0 | J8: 0 | K8: 0 | L8: 56 | M8: =C8+D8+E8-F8-G8-H8-I8-J8-K8 -> 2 | N8: =SUM(O8:T8) -> 61 | O8: 0 | P8: 1 | Q8: 6 | R8: 12 | S8: 38 | T8: 4 | U8: 4
A9: 5 | B9: Obstetri | C9: ='2025-03'!M9 -> 10 | D9: 103 | E9: 5 | F9: 4 | G9: 104 | H9: 0 | I9: 0 | J9: 0 | K9: 0 | L9: 308 | M9: =C9+D9+E9-F9-G9-H9-I9-J9-K9 -> 10 | N9: =SUM(O9:T9) -> 330 | O9: 0 | P9: 10 | Q9: 40 | R9: 82 | S9: 191 | T9: 7 | U9: 14
A10: 6 | B10: Ginekologi | C10: ='2025-03'!M10 -> 3 | D10: 23 | E10: 1 | F10: 1 | G10: 23 | H10: 0 | I10: 0 | J10: 0 | K10: 0 | L10: 94 | M10: =C10+D10+E10-F10-G10-H10-I10-J10-K10 -> 3 | N10: =SUM(O10:T10) -> 101 | O10: 0 | P10: 2 | Q10: 10 | R10: 20 | S10: 63 | T10: 6 | U10: 6
A11: 7 | B11: Bedah | C11: ='2025-03'!M11 -> 9 | D11: 50 | E11: 3 | F11: 3 | G11: 51 | H11: 0 | I11: 0 | J11: 0 | K11: 0 | L11: 249 | M11: =C11+D11+E11-F11-G11-H11-I11-J11-K11 -> 8 | N11: =SUM(O11:T11) -> 267 | O11: 0 | P11: 8 | Q11: 32 | R11: 59 | S11: 160 | T11: 8 | U11: 14
A12: 8 | B12: Bedah Orthopedi | C12: ='2025-03'!M12 -> 5 | D12: 21 | E12: 1 | F12: 1 | G12: 21 | H12: 0 | I12: 0 | J12: 0 | K12: 0 | L12: 145 | M12: =C12+D12+E12-F12-G12-H12-I12-J12-K12 -> 5 | N12: =SUM(O12:T12) -> 150 | O12: 0 | P12: 5 | Q12: 18 | R12: 33 | S12: 90 | T12: 4 | U12: 8
A13: 9 | B13: Bedah Saraf | C13: ='2025-03'!M13 -> 2 | D13: 10 | E13: 1 | F13: 1 | G13: 10 | H13: 0 | I13: 0 | J13: 0 | K13: 0 | L13: 70 | M13: =C13+D13+E13-F13-G13-H13-I13-J13-K13 -> 2 | N13: =SUM(O13:T13) -> 73 | O13: 0 | P13: 2 | Q13: 9 | R13: 16 | S13: 44 | T13: 2 | U13: 4
A14: 10 | B14: Luka Bakar | C14: ='2025-03'!M14 -> 0 | D14: 0 | E14: 0 | F14: 0 | G14: 0 | H14: 0 | I14: 0 | J14: 0 | K14: 0 | L14: 0 | M14: =C14+D14+E14-F14-G14-H14-I14-J14-K14 -> 0 | N14: =SUM(O14:T14) -> 0 | O14: 0 | P14: 0 | Q14: 0 | R14: 0 | S14: 0 | T14: 0 | U14: 0
A15: 11 | B15: Saraf | C15: ='2025-03'!M15 -> 0 | D15: 0 | E15: 0 | F15: 0 | G15: 0 | H15: 0 | I15: 0 | J15: 0 | K15: 0 | L15: 0 | M15: =C15+D15+E15-F15-G15-H15-I15-J15-K15 -> 0 | N15: =SUM(O15:T15) -> 0 | O15: 0 | P15: 0 | Q15: 0 | R15: 0 | S15: 0 | T15: 0 | U15: 0
A16: 12 | B16: Jiwa | C16: ='2025-03'!M16 -> 0 | D16: 0 | E16: 0 | F16: 0 | G16: 0 | H16: 0 | I16: 0 | J16: 0 | K16: 0 | L16: 0 | M16: =C16+D16+E16-F16-G16-H16-I16-J16-K16 -> 0 | N16: =SUM(O16:T16) -> 0 | O16: 0 | P16: 0 | Q16: 0 | R16: 0 | S16: 0 | T16: 0 | U16: 0
... A40: 36 | B40: Perinatologi | C40: ='2025-03'!M40 -> 4 | D40: 18 | E40: 3 | F40: 2 | G40: 19 | H40: 0 | I40: 0 | J40: 0 | K40: 0 | L40: 114 | M40: =C40+D40+E40-F40-G40-H40-I40-J40-K40 -> 4 | N40: =SUM(O40:T40) -> 126 | O40: 0 | P40: 0 | Q40: 0 | R40: 6 | S40: 32 | T40: 88 | U40: 6
A41: 99 | B41: TOTAL | C41: =SUM(C5:C40) -> 124 | D41: =SUM(D5:D40) -> 822 | E41: =SUM(E5:E40) -> 94 | F41: =SUM(F5:F40) -> 91 | G41: =SUM(G5:G40) -> 823 | H41: =SUM(H5:H40) -> 0 | I41: =SUM(I5:I40) -> 6 | J41: =SUM(J5:J40) -> 0 | ... U41: =SUM(U5:U40) -> 196

Sheet 2025-05
A1: RL 3.2 - Rekapitulasi Kegiatan Pelayanan Rawat Inap - Mei 2025
A2: RS Umum Demo Basangdata (fiktif) | DEMO: sandbox latihan input SIRS. Bukan aplikasi resmi Kemenkes.
A4: No | B4: Jenis Pelayanan | C4: Pasien Awal Bulan | D4: Pasien Masuk | E4: Pasien Pindahan | F4: Pasien Dipindahkan | G4: Pasien Keluar Hidup | H4: Pasien Laki-Laki Keluar Mati < 48 jam | I4: Pasien Laki-Laki Keluar Mati ≥ 48 jam | J4: Pasien Perempuan Keluar Mati < 48 jam | K4: Pasien Perempuan Keluar Mati ≥ 48 jam | L4: Jumlah Lama Dirawat | M4: Pasien Akhir Bulan (otomatis) | N4: Jumlah Hari Perawatan (otomatis) | O4: Hari Perawatan Kelas VVIP | P4: Hari Perawatan Kelas VIP | Q4: Hari Perawatan Kelas I | R4: Hari Perawatan Kelas II | S4: Hari Perawatan Kelas III | T4: Hari Perawatan Kelas Khusus | U4: Jumlah Alokasi Tempat Tidur Awal Bulan
A5: 1 | B5: Umum | C5: ='2025-04'!M5 -> 16 | D5: 117 | E5: 7 | F5: 5 | G5: 120 | H5: 0 | I5: 0 | J5: 0 | K5: 0 | L5: 464 | M5: =C5+D5+E5-F5-G5-H5-I5-J5-K5 -> 15 | N5: =SUM(O5:T5) -> 505 | O5: 0 | P5: 10 | Q5: 40 | R5: 91 | S5: 344 | T5: 20 | U5: 24
A6: 2 | B6: Penyakit Dalam | C6: ='2025-04'!M6 -> 13 | D6: 89 | E6: 8 | F6: 5 | G6: 89 | H6: 1 | I6: 0 | J6: 0 | K6: 1 | L6: 410 | M6: =C6+D6+E6-F6-G6-H6-I6-J6-K6 -> 14 | N6: =SUM(O6:T6) -> 449 | O6: 0 | P6: 9 | Q6: 45 | R6: 90 | S6: 278 | T6: 27 | U6: 20
A7: 3 | B7: Kesehatan Anak | C7: ='2025-04'!M7 -> 9 | D7: 62 | E7: 4 | F7: 2 | G7: 66 | H7: 0 | I7: 0 | J7: 0 | K7: 0 | L7: 230 | M7: =C7+D7+E7-F7-G7-H7-I7-J7-K7 -> 7 | N7: =SUM(O7:T7) -> 253 | O7: 0 | P7: 5 | Q7: 25 | R7: 51 | S7: 157 | T7: 15 | U7: 12
A8: 4 | B8: Kesehatan Remaja | C8: ='2025-04'!M8 -> 2 | D8: 14 | E8: 1 | F8: 1 | G8: 14 | H8: 0 | I8: 0 | J8: 0 | K8: 0 | L8: 56 | M8: =C8+D8+E8-F8-G8-H8-I8-J8-K8 -> 2 | N8: =SUM(O8:T8) -> 60 | O8: 0 | P8: 1 | Q8: 6 | R8: 12 | S8: 37 | T8: 4 | U8: 4
A9: 5 | B9: Obstetri | C9: ='2025-04'!M9 -> 10 | D9: 105 | E9: 5 | F9: 4 | G9: 105 | H9: 0 | I9: 1 | J9: 0 | K9: 0 | L9: 317 | M9: =C9+D9+E9-F9-G9-H9-I9-J9-K9 -> 10 | N9: =SUM(O9:T9) -> 336 | O9: 0 | P9: 10 | Q9: 40 | R9: 84 | S9: 195 | T9: 7 | U9: 14
A10: 6 | B10: Ginekologi | C10: ='2025-04'!M10 -> 3 | D10: 24 | E10: 1 | F10: 1 | G10: 23 | H10: 0 | I10: 0 | J10: 0 | K10: 0 | L10: 98 | M10: =C10+D10+E10-F10-G10-H10-I10-J10-K10 -> 4 | N10: =SUM(O10:T10) -> 101 | O10: 0 | P10: 2 | Q10: 10 | R10: 20 | S10: 63 | T10: 6 | U10: 6
A11: 7 | B11: Bedah | C11: ='2025-04'!M11 -> 8 | D11: 54 | E11: 4 | F11: 3 | G11: 53 | H11: 0 | I11: 1 | J11: 0 | K11: 0 | L11: 253 | M11: =C11+D11+E11-F11-G11-H11-I11-J11-K11 -> 9 | N11: =SUM(O11:T11) -> 276 | O11: 0 | P11: 8 | Q11: 33 | R11: 61 | S11: 166 | T11: 8 | U11: 14
A12: 8 | B12: Bedah Orthopedi | C12: ='2025-04'!M12 -> 5 | D12: 22 | E12: 2 | F12: 1 | G12: 24 | H12: 0 | I12: 0 | J12: 0 | K12: 0 | L12: 142 | M12: =C12+D12+E12-F12-G12-H12-I12-J12-K12 -> 4 | N12: =SUM(O12:T12) -> 153 | O12: 0 | P12: 5 | Q12: 18 | R12: 34 | S12: 92 | T12: 4 | U12: 8
A13: 9 | B13: Bedah Saraf | C13: ='2025-04'!M13 -> 2 | D13: 10 | E13: 1 | F13: 1 | G13: 10 | H13: 0 | I13: 0 | J13: 0 | K13: 0 | L13: 68 | M13: =C13+D13+E13-F13-G13-H13-I13-J13-K13 -> 2 | N13: =SUM(O13:T13) -> 73 | O13: 0 | P13: 2 | Q13: 9 | R13: 16 | S13: 44 | T13: 2 | U13: 4
A14: 10 | B14: Luka Bakar | C14: ='2025-04'!M14 -> 0 | D14: 0 | E14: 0 | F14: 0 | G14: 0 | H14: 0 | I14: 0 | J14: 0 | K14: 0 | L14: 0 | M14: =C14+D14+E14-F14-G14-H14-I14-J14-K14 -> 0 | N14: =SUM(O14:T14) -> 0 | O14: 0 | P14: 0 | Q14: 0 | R14: 0 | S14: 0 | T14: 0 | U14: 0
A15: 11 | B15: Saraf | C15: ='2025-04'!M15 -> 0 | D15: 0 | E15: 0 | F15: 0 | G15: 0 | H15: 0 | I15: 0 | J15: 0 | K15: 0 | L15: 0 | M15: =C15+D15+E15-F15-G15-H15-I15-J15-K15 -> 0 | N15: =SUM(O15:T15) -> 0 | O15: 0 | P15: 0 | Q15: 0 | R15: 0 | S15: 0 | T15: 0 | U15: 0
A16: 12 | B16: Jiwa | C16: ='2025-04'!M16 -> 0 | D16: 0 | E16: 0 | F16: 0 | G16: 0 | H16: 0 | I16: 0 | J16: 0 | K16: 0 | L16: 0 | M16: =C16+D16+E16-F16-G16-H16-I16-J16-K16 -> 0 | N16: =SUM(O16:T16) -> 0 | O16: 0 | P16: 0 | Q16: 0 | R16: 0 | S16: 0 | T16: 0 | U16: 0
... A40: 36 | B40: Perinatologi | C40: ='2025-04'!M40 -> 4 | D40: 21 | E40: 3 | F40: 3 | G40: 19 | H40: 0 | I40: 1 | J40: 0 | K40: 0 | L40: 125 | M40: =C40+D40+E40-F40-G40-H40-I40-J40-K40 -> 5 | N40: =SUM(O40:T40) -> 138 | O40: 0 | P40: 0 | Q40: 0 | R40: 7 | S40: 34 | T40: 97 | U40: 6
A41: 99 | B41: TOTAL | C41: =SUM(C5:C40) -> 120 | D41: =SUM(D5:D40) -> 832 | E41: =SUM(E5:E40) -> 93 | F41: =SUM(F5:F40) -> 93 | G41: =SUM(G5:G40) -> 816 | H41: =SUM(H5:H40) -> 3 | I41: =SUM(I5:I40) -> 8 | J41: =SUM(J5:J40) -> 1 | ... U41: =SUM(U5:U40) -> 196

Sheet 2025-06
A1: RL 3.2 - Rekapitulasi Kegiatan Pelayanan Rawat Inap - Juni 2025
A2: RS Umum Demo Basangdata (fiktif) | DEMO: sandbox latihan input SIRS. Bukan aplikasi resmi Kemenkes.
A4: No | B4: Jenis Pelayanan | C4: Pasien Awal Bulan | D4: Pasien Masuk | E4: Pasien Pindahan | F4: Pasien Dipindahkan | G4: Pasien Keluar Hidup | H4: Pasien Laki-Laki Keluar Mati < 48 jam | I4: Pasien Laki-Laki Keluar Mati ≥ 48 jam | J4: Pasien Perempuan Keluar Mati < 48 jam | K4: Pasien Perempuan Keluar Mati ≥ 48 jam | L4: Jumlah Lama Dirawat | M4: Pasien Akhir Bulan (otomatis) | N4: Jumlah Hari Perawatan (otomatis) | O4: Hari Perawatan Kelas VVIP | P4: Hari Perawatan Kelas VIP | Q4: Hari Perawatan Kelas I | R4: Hari Perawatan Kelas II | S4: Hari Perawatan Kelas III | T4: Hari Perawatan Kelas Khusus | U4: Jumlah Alokasi Tempat Tidur Awal Bulan
A5: 1 | B5: Umum | C5: ='2025-05'!M5 -> 15 | D5: 109 | E5: 8 | F5: 5 | G5: 111 | H5: 0 | I5: 0 | J5: 0 | K5: 0 | L5: 478 | M5: =C5+D5+E5-F5-G5-H5-I5-J5-K5 -> 16 | N5: =SUM(O5:T5) -> 495 | O5: 0 | P5: 10 | Q5: 39 | R5: 89 | S5: 337 | T5: 20 | U5: 24
A6: 2 | B6: Penyakit Dalam | C6: ='2025-05'!M6 -> 14 | D6: 78 | E6: 6 | F6: 4 | G6: 79 | H6: 0 | I6: 1 | J6: 0 | K6: 0 | L6: 380 | M6: =C6+D6+E6-F6-G6-H6-I6-J6-K6 -> 14 | N6: =SUM(O6:T6) -> 396 | O6: 0 | P6: 8 | Q6: 40 | R6: 79 | S6: 245 | T6: 24 | U6: 20
A7: 3 | B7: Kesehatan Anak | C7: ='2025-05'!M7 -> 7 | D7: 60 | E7: 4 | F7: 3 | G7: 60 | H7: 0 | I7: 1 | J7: 0 | K7: 0 | L7: 224 | M7: =C7+D7+E7-F7-G7-H7-I7-J7-K7 -> 7 | N7: =SUM(O7:T7) -> 241 | O7: 0 | P7: 5 | Q7: 24 | R7: 48 | S7: 149 | T7: 15 | U7: 12
A8: 4 | B8: Kesehatan Remaja | C8: ='2025-05'!M8 -> 2 | D8: 13 | E8: 1 | F8: 1 | G8: 13 | H8: 0 | I8: 0 | J8: 0 | K8: 0 | L8: 52 | M8: =C8+D8+E8-F8-G8-H8-I8-J8-K8 -> 2 | N8: =SUM(O8:T8) -> 55 | O8: 0 | P8: 1 | Q8: 6 | R8: 11 | S8: 34 | T8: 3 | U8: 4
A9: 5 | B9: Obstetri | C9: ='2025-05'!M9 -> 10 | D9: 106 | E9: 5 | F9: 5 | G9: 105 | H9: 0 | I9: 1 | J9: 0 | K9: 0 | L9: 301 | M9: =C9+D9+E9-F9-G9-H9-I9-J9-K9 -> 10 | N9: =SUM(O9:T9) -> 317 | O9: 0 | P9: 10 | Q9: 38 | R9: 79 | S9: 184 | T9: 6 | U9: 14
A10: 6 | B10: Ginekologi | C10: ='2025-05'!M10 -> 4 | D10: 23 | E10: 1 | F10: 1 | G10: 23 | H10: 0 | I10: 0 | J10: 0 | K10: 0 | L10: 90 | M10: =C10+D10+E10-F10-G10-H10-I10-J10-K10 -> 4 | N10: =SUM(O10:T10) -> 96 | O10: 0 | P10: 2 | Q10: 10 | R10: 19 | S10: 59 | T10: 6 | U10: 6
A11: 7 | B11: Bedah | C11: ='2025-05'!M11 -> 9 | D11: 53 | E11: 3 | F11: 3 | G11: 53 | H11: 0 | I11: 0 | J11: 0 | K11: 0 | L11: 254 | M11: =C11+D11+E11-F11-G11-H11-I11-J11-K11 -> 9 | N11: =SUM(O11:T11) -> 269 | O11: 0 | P11: 8 | Q11: 32 | R11: 59 | S11: 162 | T11: 8 | U11: 14
A12: 8 | B12: Bedah Orthopedi | C12: ='2025-05'!M12 -> 4 | D12: 19 | E12: 1 | F12: 1 | G12: 18 | H12: 0 | I12: 0 | J12: 0 | K12: 0 | L12: 132 | M12: =C12+D12+E12-F12-G12-H12-I12-J12-K12 -> 5 | N12: =SUM(O12:T12) -> 138 | O12: 0 | P12: 4 | Q12: 17 | R12: 30 | S12: 83 | T12: 4 | U12: 8
A13: 9 | B13: Bedah Saraf | C13: ='2025-05'!M13 -> 2 | D13: 8 | E13: 1 | F13: 1 | G13: 8 | H13: 0 | I13: 0 | J13: 0 | K13: 0 | L13: 60 | M13: =C13+D13+E13-F13-G13-H13-I13-J13-K13 -> 2 | N13: =SUM(O13:T13) -> 63 | O13: 0 | P13: 2 | Q13: 7 | R13: 14 | S13: 38 | T13: 2 | U13: 4
A14: 10 | B14: Luka Bakar | C14: ='2025-05'!M14 -> 0 | D14: 0 | E14: 0 | F14: 0 | G14: 0 | H14: 0 | I14: 0 | J14: 0 | K14: 0 | L14: 0 | M14: =C14+D14+E14-F14-G14-H14-I14-J14-K14 -> 0 | N14: =SUM(O14:T14) -> 0 | O14: 0 | P14: 0 | Q14: 0 | R14: 0 | S14: 0 | T14: 0 | U14: 0
A15: 11 | B15: Saraf | C15: ='2025-05'!M15 -> 0 | D15: 0 | E15: 0 | F15: 0 | G15: 0 | H15: 0 | I15: 0 | J15: 0 | K15: 0 | L15: 0 | M15: =C15+D15+E15-F15-G15-H15-I15-J15-K15 -> 0 | N15: =SUM(O15:T15) -> 0 | O15: 0 | P15: 0 | Q15: 0 | R15: 0 | S15: 0 | T15: 0 | U15: 0
A16: 12 | B16: Jiwa | C16: ='2025-05'!M16 -> 0 | D16: 0 | E16: 0 | F16: 0 | G16: 0 | H16: 0 | I16: 0 | J16: 0 | K16: 0 | L16: 0 | M16: =C16+D16+E16-F16-G16-H16-I16-J16-K16 -> 0 | N16: =SUM(O16:T16) -> 0 | O16: 0 | P16: 0 | Q16: 0 | R16: 0 | S16: 0 | T16: 0 | U16: 0
... A40: 36 | B40: Perinatologi | C40: ='2025-05'!M40 -> 5 | D40: 19 | E40: 3 | F40: 3 | G40: 19 | H40: 0 | I40: 0 | J40: 0 | K40: 0 | L40: 119 | M40: =C40+D40+E40-F40-G40-H40-I40-J40-K40 -> 5 | N40: =SUM(O40:T40) -> 126 | O40: 0 | P40: 0 | Q40: 0 | R40: 6 | S40: 32 | T40: 88 | U40: 6
A41: 99 | B41: TOTAL | C41: =SUM(C5:C40) -> 121 | D41: =SUM(D5:D40) -> 792 | E41: =SUM(E5:E40) -> 89 | F41: =SUM(F5:F40) -> 90 | G41: =SUM(G5:G40) -> 777 | H41: =SUM(H5:H40) -> 1 | I41: =SUM(I5:I40) -> 7 | J41: =SUM(J5:J40) -> 0 | ... U41: =SUM(U5:U40) -> 196

Sheet 2025-07
A1: RL 3.2 - Rekapitulasi Kegiatan Pelayanan Rawat Inap - Juli 2025
A2: RS Umum Demo Basangdata (fiktif) | DEMO: sandbox latihan input SIRS. Bukan aplikasi resmi Kemenkes.
A4: No | B4: Jenis Pelayanan | C4: Pasien Awal Bulan | D4: Pasien Masuk | E4: Pasien Pindahan | F4: Pasien Dipindahkan | G4: Pasien Keluar Hidup | H4: Pasien Laki-Laki Keluar Mati < 48 jam | I4: Pasien Laki-Laki Keluar Mati ≥ 48 jam | J4: Pasien Perempuan Keluar Mati < 48 jam | K4: Pasien Perempuan Keluar Mati ≥ 48 jam | L4: Jumlah Lama Dirawat | M4: Pasien Akhir Bulan (otomatis) | N4: Jumlah Hari Perawatan (otomatis) | O4: Hari Perawatan Kelas VVIP | P4: Hari Perawatan Kelas VIP | Q4: Hari Perawatan Kelas I | R4: Hari Perawatan Kelas II | S4: Hari Perawatan Kelas III | T4: Hari Perawatan Kelas Khusus | U4: Jumlah Alokasi Tempat Tidur Awal Bulan
A5: 1 | B5: Umum | C5: ='2025-06'!M5 -> 16 | D5: 111 | E5: 7 | F5: 5 | G5: 111 | H5: 0 | I5: 0 | J5: 0 | K5: 0 | L5: 486 | M5: =C5+D5+E5-F5-G5-H5-I5-J5-K5 -> 18 | N5: =SUM(O5:T5) -> 505 | O5: 0 | P5: 10 | Q5: 40 | R5: 91 | S5: 344 | T5: 20 | U5: 26
A6: 2 | B6: Penyakit Dalam | C6: ='2025-06'!M6 -> 14 | D6: 82 | E6: 7 | F6: 4 | G6: 84 | H6: 0 | I6: 0 | J6: 0 | K6: 0 | L6: 360 | M6: =C6+D6+E6-F6-G6-H6-I6-J6-K6 -> 15 | N6: =SUM(O6:T6) -> 397 | O6: 0 | P6: 8 | Q6: 40 | R6: 79 | S6: 246 | T6: 24 | U6: 20
A7: 3 | B7: Kesehatan Anak | C7: ='2025-06'!M7 -> 7 | D7: 63 | E7: 3 | F7: 3 | G7: 60 | H7: 0 | I7: 1 | J7: 0 | K7: 0 | L7: 240 | M7: =C7+D7+E7-F7-G7-H7-I7-J7-K7 -> 9 | N7: =SUM(O7:T7) -> 248 | O7: 0 | P7: 5 | Q7: 25 | R7: 49 | S7: 154 | T7: 15 | U7: 12
A8: 4 | B8: Kesehatan Remaja | C8: ='2025-06'!M8 -> 2 | D8: 12 | E8: 1 | F8: 1 | G8: 12 | H8: 0 | I8: 0 | J8: 0 | K8: 0 | L8: 49 | M8: =C8+D8+E8-F8-G8-H8-I8-J8-K8 -> 2 | N8: =SUM(O8:T8) -> 52 | O8: 0 | P8: 1 | Q8: 5 | R8: 11 | S8: 32 | T8: 3 | U8: 4
A9: 5 | B9: Obstetri | C9: ='2025-06'!M9 -> 10 | D9: 97 | E9: 5 | F9: 4 | G9: 98 | H9: 0 | I9: 0 | J9: 0 | K9: 0 | L9: 282 | M9: =C9+D9+E9-F9-G9-H9-I9-J9-K9 -> 10 | N9: =SUM(O9:T9) -> 308 | O9: 0 | P9: 9 | Q9: 37 | R9: 77 | S9: 179 | T9: 6 | U9: 14
A10: 6 | B10: Ginekologi | C10: ='2025-06'!M10 -> 4 | D10: 22 | E10: 1 | F10: 1 | G10: 23 | H10: 0 | I10: 0 | J10: 0 | K10: 0 | L10: 91 | M10: =C10+D10+E10-F10-G10-H10-I10-J10-K10 -> 3 | N10: =SUM(O10:T10) -> 99 | O10: 0 | P10: 2 | Q10: 10 | R10: 20 | S10: 61 | T10: 6 | U10: 6
A11: 7 | B11: Bedah | C11: ='2025-06'!M11 -> 9 | D11: 52 | E11: 3 | F11: 2 | G11: 51 | H11: 1 | I11: 0 | J11: 0 | K11: 1 | L11: 257 | M11: =C11+D11+E11-F11-G11-H11-I11-J11-K11 -> 9 | N11: =SUM(O11:T11) -> 268 | O11: 0 | P11: 8 | Q11: 32 | R11: 59 | S11: 161 | T11: 8 | U11: 14
A12: 8 | B12: Bedah Orthopedi | C12: ='2025-06'!M12 -> 5 | D12: 20 | E12: 1 | F12: 1 | G12: 20 | H12: 0 | I12: 0 | J12: 0 | K12: 0 | L12: 138 | M12: =C12+D12+E12-F12-G12-H12-I12-J12-K12 -> 5 | N12: =SUM(O12:T12) -> 145 | O12: 0 | P12: 4 | Q12: 18 | R12: 32 | S12: 87 | T12: 4 | U12: 8
A13: 9 | B13: Bedah Saraf | C13: ='2025-06'!M13 -> 2 | D13: 9 | E13: 1 | F13: 1 | G13: 9 | H13: 0 | I13: 0 | J13: 0 | K13: 0 | L13: 58 | M13: =C13+D13+E13-F13-G13-H13-I13-J13-K13 -> 2 | N13: =SUM(O13:T13) -> 64 | O13: 0 | P13: 2 | Q13: 8 | R13: 14 | S13: 38 | T13: 2 | U13: 4
A14: 10 | B14: Luka Bakar | C14: ='2025-06'!M14 -> 0 | D14: 0 | E14: 0 | F14: 0 | G14: 0 | H14: 0 | I14: 0 | J14: 0 | K14: 0 | L14: 0 | M14: =C14+D14+E14-F14-G14-H14-I14-J14-K14 -> 0 | N14: =SUM(O14:T14) -> 0 | O14: 0 | P14: 0 | Q14: 0 | R14: 0 | S14: 0 | T14: 0 | U14: 0
A15: 11 | B15: Saraf | C15: ='2025-06'!M15 -> 0 | D15: 0 | E15: 0 | F15: 0 | G15: 0 | H15: 0 | I15: 0 | J15: 0 | K15: 0 | L15: 0 | M15: =C15+D15+E15-F15-G15-H15-I15-J15-K15 -> 0 | N15: =SUM(O15:T15) -> 0 | O15: 0 | P15: 0 | Q15: 0 | R15: 0 | S15: 0 | T15: 0 | U15: 0
A16: 12 | B16: Jiwa | C16: ='2025-06'!M16 -> 0 | D16: 0 | E16: 0 | F16: 0 | G16: 0 | H16: 0 | I16: 0 | J16: 0 | K16: 0 | L16: 0 | M16: =C16+D16+E16-F16-G16-H16-I16-J16-K16 -> 0 | N16: =SUM(O16:T16) -> 0 | O16: 0 | P16: 0 | Q16: 0 | R16: 0 | S16: 0 | T16: 0 | U16: 0
... A40: 36 | B40: Perinatologi | C40: ='2025-06'!M40 -> 5 | D40: 18 | E40: 3 | F40: 2 | G40: 19 | H40: 0 | I40: 1 | J40: 0 | K40: 0 | L40: 112 | M40: =C40+D40+E40-F40-G40-H40-I40-J40-K40 -> 4 | N40: =SUM(O40:T40) -> 121 | O40: 0 | P40: 0 | Q40: 0 | R40: 6 | S40: 30 | T40: 85 | U40: 6
A41: 99 | B41: TOTAL | C41: =SUM(C5:C40) -> 125 | D41: =SUM(D5:D40) -> 785 | E41: =SUM(E5:E40) -> 89 | F41: =SUM(F5:F40) -> 85 | G41: =SUM(G5:G40) -> 779 | H41: =SUM(H5:H40) -> 3 | I41: =SUM(I5:I40) -> 3 | J41: =SUM(J5:J40) -> 0 | ... U41: =SUM(U5:U40) -> 198

Sheet 2025-08
A1: RL 3.2 - Rekapitulasi Kegiatan Pelayanan Rawat Inap - Agustus 2025
A2: RS Umum Demo Basangdata (fiktif) | DEMO: sandbox latihan input SIRS. Bukan aplikasi resmi Kemenkes.
A4: No | B4: Jenis Pelayanan | C4: Pasien Awal Bulan | D4: Pasien Masuk | E4: Pasien Pindahan | F4: Pasien Dipindahkan | G4: Pasien Keluar Hidup | H4: Pasien Laki-Laki Keluar Mati < 48 jam | I4: Pasien Laki-Laki Keluar Mati ≥ 48 jam | J4: Pasien Perempuan Keluar Mati < 48 jam | K4: Pasien Perempuan Keluar Mati ≥ 48 jam | L4: Jumlah Lama Dirawat | M4: Pasien Akhir Bulan (otomatis) | N4: Jumlah Hari Perawatan (otomatis) | O4: Hari Perawatan Kelas VVIP | P4: Hari Perawatan Kelas VIP | Q4: Hari Perawatan Kelas I | R4: Hari Perawatan Kelas II | S4: Hari Perawatan Kelas III | T4: Hari Perawatan Kelas Khusus | U4: Jumlah Alokasi Tempat Tidur Awal Bulan
A5: 1 | B5: Umum | C5: ='2025-07'!M5 -> 18 | D5: 113 | E5: 7 | F5: 4 | G5: 117 | H5: 0 | I5: 0 | J5: 0 | K5: 0 | L5: 452 | M5: =C5+D5+E5-F5-G5-H5-I5-J5-K5 -> 17 | N5: =SUM(O5:T5) -> 474 | O5: 0 | P5: 10 | Q5: 38 | R5: 85 | S5: 322 | T5: 19 | U5: 24
A6: 2 | B6: Penyakit Dalam | C6: ='2025-07'!M6 -> 15 | D6: 84 | E6: 6 | F6: 5 | G6: 84 | H6: 1 | I6: 1 | J6: 0 | K6: 1 | L6: 368 | M6: =C6+D6+E6-F6-G6-H6-I6-J6-K6 -> 13 | N6: =SUM(O6:T6) -> 392 | O6: 0 | P6: 8 | Q6: 39 | R6: 78 | S6: 243 | T6: 24 | U6: 20
A7: 3 | B7: Kesehatan Anak | C7: ='2025-07'!M7 -> 9 | D7: 62 | E7: 4 | F7: 2 | G7: 66 | H7: 0 | I7: 0 | J7: 0 | K7: 0 | L7: 235 | M7: =C7+D7+E7-F7-G7-H7-I7-J7-K7 -> 7 | N7: =SUM(O7:T7) -> 244 | O7: 0 | P7: 5 | Q7: 24 | R7: 49 | S7: 151 | T7: 15 | U7: 12
A8: 4 | B8: Kesehatan Remaja | C8: ='2025-07'!M8 -> 2 | D8: 12 | E8: 1 | F8: 1 | G8: 12 | H8: 0 | I8: 0 | J8: 0 | K8: 0 | L8: 48 | M8: =C8+D8+E8-F8-G8-H8-I8-J8-K8 -> 2 | N8: =SUM(O8:T8) -> 52 | O8: 0 | P8: 1 | Q8: 5 | R8: 11 | S8: 32 | T8: 3 | U8: 4
A9: 5 | B9: Obstetri | C9: ='2025-07'!M9 -> 10 | D9: 92 | E9: 4 | F9: 3 | G9: 93 | H9: 0 | I9: 0 | J9: 0 | K9: 0 | L9: 265 | M9: =C9+D9+E9-F9-G9-H9-I9-J9-K9 -> 10 | N9: =SUM(O9:T9) -> 288 | O9: 0 | P9: 9 | Q9: 34 | R9: 72 | S9: 167 | T9: 6 | U9: 14
A10: 6 | B10: Ginekologi | C10: ='2025-07'!M10 -> 3 | D10: 24 | E10: 1 | F10: 1 | G10: 24 | H10: 0 | I10: 0 | J10: 0 | K10: 0 | L10: 95 | M10: =C10+D10+E10-F10-G10-H10-I10-J10-K10 -> 3 | N10: =SUM(O10:T10) -> 102 | O10: 0 | P10: 2 | Q10: 10 | R10: 21 | S10: 63 | T10: 6 | U10: 6
A11: 7 | B11: Bedah | C11: ='2025-07'!M11 -> 9 | D11: 49 | E11: 3 | F11: 3 | G11: 49 | H11: 0 | I11: 0 | J11: 0 | K11: 0 | L11: 244 | M11: =C11+D11+E11-F11-G11-H11-I11-J11-K11 -> 9 | N11: =SUM(O11:T11) -> 266 | O11: 0 | P11: 8 | Q11: 32 | R11: 58 | S11: 160 | T11: 8 | U11: 14
A12: 8 | B12: Bedah Orthopedi | C12: ='2025-07'!M12 -> 5 | D12: 21 | E12: 1 | F12: 1 | G12: 21 | H12: 0 | I12: 0 | J12: 0 | K12: 0 | L12: 136 | M12: =C12+D12+E12-F12-G12-H12-I12-J12-K12 -> 5 | N12: =SUM(O12:T12) -> 140 | O12: 0 | P12: 4 | Q12: 17 | R12: 31 | S12: 84 | T12: 4 | U12: 8
A13: 9 | B13: Bedah Saraf | C13: ='2025-07'!M13 -> 2 | D13: 9 | E13: 1 | F13: 1 | G13: 9 | H13: 0 | I13: 0 | J13: 0 | K13: 0 | L13: 62 | M13: =C13+D13+E13-F13-G13-H13-I13-J13-K13 -> 2 | N13: =SUM(O13:T13) -> 65 | O13: 0 | P13: 2 | Q13: 8 | R13: 14 | S13: 39 | T13: 2 | U13: 4
A14: 10 | B14: Luka Bakar | C14: ='2025-07'!M14 -> 0 | D14: 0 | E14: 0 | F14: 0 | G14: 0 | H14: 0 | I14: 0 | J14: 0 | K14: 0 | L14: 0 | M14: =C14+D14+E14-F14-G14-H14-I14-J14-K14 -> 0 | N14: =SUM(O14:T14) -> 0 | O14: 0 | P14: 0 | Q14: 0 | R14: 0 | S14: 0 | T14: 0 | U14: 0
A15: 11 | B15: Saraf | C15: ='2025-07'!M15 -> 0 | D15: 0 | E15: 0 | F15: 0 | G15: 0 | H15: 0 | I15: 0 | J15: 0 | K15: 0 | L15: 0 | M15: =C15+D15+E15-F15-G15-H15-I15-J15-K15 -> 0 | N15: =SUM(O15:T15) -> 0 | O15: 0 | P15: 0 | Q15: 0 | R15: 0 | S15: 0 | T15: 0 | U15: 0
A16: 12 | B16: Jiwa | C16: ='2025-07'!M16 -> 0 | D16: 0 | E16: 0 | F16: 0 | G16: 0 | H16: 0 | I16: 0 | J16: 0 | K16: 0 | L16: 0 | M16: =C16+D16+E16-F16-G16-H16-I16-J16-K16 -> 0 | N16: =SUM(O16:T16) -> 0 | O16: 0 | P16: 0 | Q16: 0 | R16: 0 | S16: 0 | T16: 0 | U16: 0
... A40: 36 | B40: Perinatologi | C40: ='2025-07'!M40 -> 4 | D40: 20 | E40: 3 | F40: 2 | G40: 20 | H40: 0 | I40: 1 | J40: 0 | K40: 0 | L40: 114 | M40: =C40+D40+E40-F40-G40-H40-I40-J40-K40 -> 4 | N40: =SUM(O40:T40) -> 125 | O40: 0 | P40: 0 | Q40: 0 | R40: 6 | S40: 31 | T40: 88 | U40: 6
A41: 99 | B41: TOTAL | C41: =SUM(C5:C40) -> 126 | D41: =SUM(D5:D40) -> 775 | E41: =SUM(E5:E40) -> 86 | F41: =SUM(F5:F40) -> 84 | G41: =SUM(G5:G40) -> 770 | H41: =SUM(H5:H40) -> 2 | I41: =SUM(I5:I40) -> 6 | J41: =SUM(J5:J40) -> 0 | ... U41: =SUM(U5:U40) -> 196

Sheet 2025-09
A1: RL 3.2 - Rekapitulasi Kegiatan Pelayanan Rawat Inap - September 2025
A2: RS Umum Demo Basangdata (fiktif) | DEMO: sandbox latihan input SIRS. Bukan aplikasi resmi Kemenkes.
A4: No | B4: Jenis Pelayanan | C4: Pasien Awal Bulan | D4: Pasien Masuk | E4: Pasien Pindahan | F4: Pasien Dipindahkan | G4: Pasien Keluar Hidup | H4: Pasien Laki-Laki Keluar Mati < 48 jam | I4: Pasien Laki-Laki Keluar Mati ≥ 48 jam | J4: Pasien Perempuan Keluar Mati < 48 jam | K4: Pasien Perempuan Keluar Mati ≥ 48 jam | L4: Jumlah Lama Dirawat | M4: Pasien Akhir Bulan (otomatis) | N4: Jumlah Hari Perawatan (otomatis) | O4: Hari Perawatan Kelas VVIP | P4: Hari Perawatan Kelas VIP | Q4: Hari Perawatan Kelas I | R4: Hari Perawatan Kelas II | S4: Hari Perawatan Kelas III | T4: Hari Perawatan Kelas Khusus | U4: Jumlah Alokasi Tempat Tidur Awal Bulan
A5: 1 | B5: Umum | C5: ='2025-08'!M5 -> 17 | D5: 96 | E5: 7 | F5: 4 | G5: 99 | H5: 1 | I5: 0 | J5: 0 | K5: 1 | L5: 419 | M5: =C5+D5+E5-F5-G5-H5-I5-J5-K5 -> 15 | N5: =SUM(O5:T5) -> 458 | O5: 0 | P5: 9 | Q5: 37 | R5: 83 | S5: 311 | T5: 18 | U5: 24
A6: 2 | B6: Penyakit Dalam | C6: ='2025-08'!M6 -> 13 | D6: 78 | E6: 5 | F6: 5 | G6: 76 | H6: 0 | I6: 0 | J6: 0 | K6: 0 | L6: 371 | M6: =C6+D6+E6-F6-G6-H6-I6-J6-K6 -> 15 | N6: =SUM(O6:T6) -> 400 | O6: 0 | P6: 8 | Q6: 40 | R6: 80 | S6: 248 | T6: 24 | U6: 20
A7: 3 | B7: Kesehatan Anak | C7: ='2025-08'!M7 -> 7 | D7: 55 | E7: 3 | F7: 2 | G7: 56 | H7: 0 | I7: 0 | J7: 0 | K7: 0 | L7: 204 | M7: =C7+D7+E7-F7-G7-H7-I7-J7-K7 -> 7 | N7: =SUM(O7:T7) -> 219 | O7: 0 | P7: 4 | Q7: 22 | R7: 44 | S7: 136 | T7: 13 | U7: 12
A8: 4 | B8: Kesehatan Remaja | C8: ='2025-08'!M8 -> 2 | D8: 12 | E8: 1 | F8: 1 | G8: 12 | H8: 0 | I8: 0 | J8: 0 | K8: 0 | L8: 50 | M8: =C8+D8+E8-F8-G8-H8-I8-J8-K8 -> 2 | N8: =SUM(O8:T8) -> 52 | O8: 0 | P8: 1 | Q8: 5 | R8: 11 | S8: 32 | T8: 3 | U8: 4
A9: 5 | B9: Obstetri | C9: ='2025-08'!M9 -> 10 | D9: 96 | E9: 5 | F9: 4 | G9: 98 | H9: 0 | I9: 0 | J9: 0 | K9: 0 | L9: 275 | M9: =C9+D9+E9-F9-G9-H9-I9-J9-K9 -> 9 | N9: =SUM(O9:T9) -> 296 | O9: 0 | P9: 9 | Q9: 35 | R9: 74 | S9: 172 | T9: 6 | U9: 14
A10: 6 | B10: Ginekologi | C10: ='2025-08'!M10 -> 3 | D10: 19 | E10: 1 | F10: 1 | G10: 19 | H10: 0 | I10: 0 | J10: 0 | K10: 0 | L10: 82 | M10: =C10+D10+E10-F10-G10-H10-I10-J10-K10 -> 3 | N10: =SUM(O10:T10) -> 89 | O10: 0 | P10: 2 | Q10: 9 | R10: 18 | S10: 55 | T10: 5 | U10: 6
A11: 7 | B11: Bedah | C11: ='2025-08'!M11 -> 9 | D11: 43 | E11: 3 | F11: 3 | G11: 43 | H11: 0 | I11: 0 | J11: 0 | K11: 0 | L11: 233 | M11: =C11+D11+E11-F11-G11-H11-I11-J11-K11 -> 9 | N11: =SUM(O11:T11) -> 243 | O11: 0 | P11: 7 | Q11: 29 | R11: 54 | S11: 146 | T11: 7 | U11: 14
A12: 8 | B12: Bedah Orthopedi | C12: ='2025-08'!M12 -> 5 | D12: 21 | E12: 1 | F12: 1 | G12: 21 | H12: 0 | I12: 0 | J12: 0 | K12: 0 | L12: 125 | M12: =C12+D12+E12-F12-G12-H12-I12-J12-K12 -> 5 | N12: =SUM(O12:T12) -> 138 | O12: 0 | P12: 4 | Q12: 17 | R12: 30 | S12: 83 | T12: 4 | U12: 8
A13: 9 | B13: Bedah Saraf | C13: ='2025-08'!M13 -> 2 | D13: 7 | E13: 1 | F13: 1 | G13: 7 | H13: 0 | I13: 0 | J13: 0 | K13: 0 | L13: 59 | M13: =C13+D13+E13-F13-G13-H13-I13-J13-K13 -> 2 | N13: =SUM(O13:T13) -> 62 | O13: 0 | P13: 2 | Q13: 7 | R13: 14 | S13: 37 | T13: 2 | U13: 4
A14: 10 | B14: Luka Bakar | C14: ='2025-08'!M14 -> 0 | D14: 0 | E14: 0 | F14: 0 | G14: 0 | H14: 0 | I14: 0 | J14: 0 | K14: 0 | L14: 0 | M14: =C14+D14+E14-F14-G14-H14-I14-J14-K14 -> 0 | N14: =SUM(O14:T14) -> 0 | O14: 0 | P14: 0 | Q14: 0 | R14: 0 | S14: 0 | T14: 0 | U14: 0
A15: 11 | B15: Saraf | C15: ='2025-08'!M15 -> 0 | D15: 0 | E15: 0 | F15: 0 | G15: 0 | H15: 0 | I15: 0 | J15: 0 | K15: 0 | L15: 0 | M15: =C15+D15+E15-F15-G15-H15-I15-J15-K15 -> 0 | N15: =SUM(O15:T15) -> 0 | O15: 0 | P15: 0 | Q15: 0 | R15: 0 | S15: 0 | T15: 0 | U15: 0
A16: 12 | B16: Jiwa | C16: ='2025-08'!M16 -> 0 | D16: 0 | E16: 0 | F16: 0 | G16: 0 | H16: 0 | I16: 0 | J16: 0 | K16: 0 | L16: 0 | M16: =C16+D16+E16-F16-G16-H16-I16-J16-K16 -> 0 | N16: =SUM(O16:T16) -> 0 | O16: 0 | P16: 0 | Q16: 0 | R16: 0 | S16: 0 | T16: 0 | U16: 0
